File: XRD_synthetic_mixture.csv
Measurement conditions,,,
Sample identification,m-M1-As Noturn 06-04-23,,
Comment,,,
Anode material,Cu,,
K-Alpha1 wavelength,1.540598,,
K-Alpha2 wavelength,1.544426,,
Ratio K-Alpha2/K-Alpha1,0.5,,
Divergence slit,Fixed,0.76mm,
Monochromator used,NO,,
Generator voltage,40,,
Tube current,15,,
File date and time,06/abr./2023 09:10,,
Unit cell,,,
h k l, 0 0 0,,
Scan axis,Gonio,,
Scan range,5.002,49.99992804,
Scan step size,0.0108664,,
No. of points,4141,,
Scan type,CONTINUOUS,,
Time per step,48.195,,
[Scan points],,,
Mesurements,,,
Angle, TimePerStep, Intensity, ESD
5.00743322,48.195,4143,64.3661
5.04003254,48.195,4183,64.6761
5.07263186,48.195,4164,64.5291
5.10523118,48.195,4165,64.5368
5.1378305,48.195,4108,64.0937
5.17042982,48.195,4055,63.6789
5.20302914,48.195,3977,63.0635
5.23562846,48.195,3939,62.7615
5.26822778,48.195,3928,62.6738
5.3008271,48.195,4088,63.9375
5.33342642,48.195,4011,63.3325
5.36602574,48.195,3947,62.8252
5.39862506,48.195,3940,62.7694
5.43122438,48.195,4010,63.3246
5.4638237,48.195,3867,62.1852
5.49642302,48.195,4014,63.3561
5.52902234,48.195,3976,63.0555
5.56162166,48.195,4006,63.293
5.59422098,48.195,4017,63.3798
5.6268203,48.195,4044,63.5925
5.65941962,48.195,4045,63.6003
5.69201894,48.195,4101,64.0391
5.72461826,48.195,4114,64.1405
5.75721758,48.195,4069,63.7887
5.7898169,48.195,3983,63.111
5.82241622,48.195,4024,63.435
5.85501554,48.195,4066,63.7652
5.88761486,48.195,4249,65.1844
5.92021418,48.195,4066,63.7652
5.9528135,48.195,4110,64.1093
5.98541282,48.195,4174,64.6065
6.01801214,48.195,4161,64.5058
6.05061146,48.195,4189,64.7225
6.08321078,48.195,4272,65.3605
6.1158101,48.195,4234,65.0692
6.14840942,48.195,4163,64.5213
6.18100874,48.195,4128,64.2495
6.21360806,48.195,4069,63.7887
6.24620738,48.195,4207,64.8614
6.2788067,48.195,4262,65.284
6.31140602,48.195,4321,65.7343
6.34400534,48.195,4291,65.5057
6.37660466,48.195,4372,66.1211
6.40920398,48.195,4316,65.6963
6.4418033,48.195,4352,65.9697
6.47440262,48.195,4210,64.8845
6.50700194,48.195,4352,65.9697
6.53960126,48.195,4460,66.7832
6.57220058,48.195,4441,66.6408
6.6047999,48.195,4470,66.8581
6.63739922,48.195,4391,66.2646
6.66999854,48.195,4462,66.7982
6.70259786,48.195,4414,66.4379
6.73519718,48.195,4486,66.9776
6.7677965,48.195,4549,67.4463
6.80039582,48.195,4395,66.2948
6.83299514,48.195,4474,66.888
6.86559446,48.195,4655,68.2276
6.89819378,48.195,4549,67.4463
6.9307931,48.195,4676,68.3813
6.96339242,48.195,4567,67.5796
6.99599174,48.195,4752,68.9348
7.02859106,48.195,4605,67.8602
7.06119038,48.195,4711,68.6367
7.0937897,48.195,4627,68.0221
7.12638902,48.195,4544,67.4092
7.15898834,48.195,4659,68.2569
7.19158766,48.195,4684,68.4398
7.22418698,48.195,4675,68.374
7.2567863,48.195,4748,68.9057
7.28938562,48.195,4658,68.2495
7.32198494,48.195,4712,68.644
7.35458426,48.195,4717,68.6804
7.38718358,48.195,4776,69.1086
7.4197829,48.195,4798,69.2676
7.45238222,48.195,4775,69.1014
7.48498154,48.195,4762,69.0072
7.51758086,48.195,4852,69.6563
7.55018018,48.195,4719,68.695
7.5827795,48.195,4895,69.9643
7.61537882,48.195,4854,69.6707
7.64797814,48.195,5005,70.746
7.68057746,48.195,4853,69.6635
7.71317678,48.195,4872,69.7997
7.7457761,48.195,4951,70.3633
7.77837542,48.195,4941,70.2922
7.81097474,48.195,4970,70.4982
7.84357406,48.195,4932,70.2282
7.87617338,48.195,4897,69.9786
7.9087727,48.195,5026,70.8943
7.94137202,48.195,5059,71.1266
7.97397134,48.195,4967,70.4769
8.00657066,48.195,4852,69.6563
8.03916998,48.195,5088,71.3302
8.0717693,48.195,5004,70.739
8.10436862,48.195,5049,71.0563
8.13696794,48.195,4987,70.6187
8.16956726,48.195,5169,71.8958
8.20216658,48.195,5147,71.7426
8.2347659,48.195,5189,72.0347
8.26736522,48.195,5110,71.4843
8.29996454,48.195,5081,71.2811
8.33256386,48.195,5134,71.6519
8.36516318,48.195,5137,71.6729
8.3977625,48.195,5193,72.0625
8.43036182,48.195,5136,71.6659
8.46296114,48.195,5206,72.1526
8.49556046,48.195,5144,71.7217
8.52815978,48.195,5237,72.3671
8.5607591,48.195,5187,72.0208
8.59335842,48.195,5249,72.45
8.62595774,48.195,5243,72.4086
8.65855706,48.195,5067,71.1829
8.69115638,48.195,5315,72.904
8.7237557,48.195,5263,72.5465
8.75635502,48.195,5093,71.3653
8.78895434,48.195,5272,72.6085
8.82155366,48.195,5264,72.5534
8.85415298,48.195,5207,72.1595
8.8867523,48.195,5333,73.0274
8.91935162,48.195,5416,73.5935
8.95195094,48.195,5275,72.6292
8.98455026,48.195,5244,72.4155
9.01714958,48.195,5352,73.1574
9.0497489,48.195,5414,73.5799
9.08234822,48.195,5203,72.1318
9.11494754,48.195,5368,73.2666
9.14754686,48.195,5369,73.2735
9.18014618,48.195,5306,72.8423
9.2127455,48.195,5271,72.6017
9.24534482,48.195,5382,73.3621
9.27794414,48.195,5377,73.328
9.31054346,48.195,5352,73.1574
9.34314278,48.195,5326,72.9794
9.3757421,48.195,5518,74.2832
9.40834142,48.195,5500,74.162
9.44094074,48.195,5431,73.6953
9.47354006,48.195,5378,73.3348
9.50613938,48.195,5446,73.797
9.5387387,48.195,5499,74.1552
9.57133802,48.195,5590,74.7663
9.60393734,48.195,5443,73.7767
9.63653666,48.195,5542,74.4446
9.66913598,48.195,5495,74.1283
9.7017353,48.195,5435,73.7225
9.73433462,48.195,5477,74.0068
9.76693394,48.195,5496,74.135
9.79953326,48.195,5456,73.8647
9.83213258,48.195,5575,74.6659
9.8647319,48.195,5588,74.7529
9.89733122,48.195,5599,74.8265
9.92993054,48.195,5536,74.4043
9.96252986,48.195,5612,74.9133
9.99512918,48.195,5490,74.0945
10.0277285,48.195,5646,75.1399
10.06032782,48.195,5589,74.7596
10.09292714,48.195,5640,75.0999
10.12552646,48.195,5644,75.1266
10.15812578,48.195,5685,75.3989
10.1907251,48.195,5682,75.379
10.22332442,48.195,5483,74.0473
10.25592374,48.195,5573,74.6525
10.28852306,48.195,5585,74.7329
10.32112238,48.195,5653,75.1864
10.3537217,48.195,5507,74.2092
10.38632102,48.195,5477,74.0068
10.41892034,48.195,5657,75.213
10.45151966,48.195,5527,74.3438
10.48411898,48.195,5741,75.7694
10.5167183,48.195,5571,74.6391
10.54931762,48.195,5656,75.2064
10.58191694,48.195,5702,75.5116
10.61451626,48.195,5795,76.1249
10.64711558,48.195,5810,76.2234
10.6797149,48.195,5713,75.5844
10.71231422,48.195,5757,75.8749
10.74491354,48.195,5666,75.2728
10.77751286,48.195,5573,74.6525
10.81011218,48.195,5779,76.0197
10.8427115,48.195,5645,75.1332
10.87531082,48.195,5849,76.4788
10.90791014,48.195,5691,75.4387
10.94050946,48.195,5834,76.3806
10.97310878,48.195,5762,75.9078
11.0057081,48.195,5722,75.6439
11.03830742,48.195,5783,76.046
11.07090674,48.195,5584,74.7262
11.10350606,48.195,5658,75.2197
11.13610538,48.195,5957,77.1816
11.1687047,48.195,5975,77.2981
11.20130402,48.195,5894,76.7724
11.23390334,48.195,5995,77.4274
11.26650266,48.195,6074,77.9359
11.29910198,48.195,6119,78.224
11.3317013,48.195,6122,78.2432
11.36430062,48.195,6269,79.177
11.39689994,48.195,6305,79.404
11.42949926,48.195,6119,78.224
11.46209858,48.195,6444,80.2745
11.4946979,48.195,6487,80.5419
11.52729722,48.195,6870,82.8855
11.55989654,48.195,7312,85.5102
11.59249586,48.195,8058,89.7664
11.62509518,48.195,8459,91.9728
11.6576945,48.195,8642,92.9624
11.69029382,48.195,9791,98.9495
11.72289314,48.195,11157,105.6267
11.75549246,48.195,9438,97.1494
11.78809178,48.195,10647,103.1843
11.8206911,48.195,13181,114.8085
11.85329042,48.195,16705,129.2478
11.88588974,48.195,14931,122.1925
11.91848906,48.195,8433,91.8314
11.95108838,48.195,6378,79.8624
11.9836877,48.195,5973,77.2852
12.01628702,48.195,6028,77.6402
12.04888634,48.195,6046,77.756
12.08148566,48.195,6033,77.6724
12.11408498,48.195,6005,77.4919
12.1466843,48.195,6085,78.0064
12.17928362,48.195,6052,77.7946
12.21188294,48.195,6023,77.608
12.24448226,48.195,5945,77.1038
12.27708158,48.195,5949,77.1298
12.3096809,48.195,6086,78.0128
12.34228022,48.195,5971,77.2722
12.37487954,48.195,6019,77.5822
12.40747886,48.195,6198,78.7274
12.44007818,48.195,6041,77.7239
12.4726775,48.195,6146,78.3964
12.50527682,48.195,5915,76.909
12.53787614,48.195,6073,77.9295
12.57047546,48.195,6147,78.4028
12.60307478,48.195,6193,78.6956
12.6356741,48.195,6057,77.8267
12.66827342,48.195,6130,78.2943
12.70087274,48.195,6201,78.7464
12.73347206,48.195,6230,78.9303
12.76607138,48.195,6103,78.1217
12.7986707,48.195,6068,77.8974
12.83127002,48.195,6109,78.1601
12.86386934,48.195,6230,78.9303
12.89646866,48.195,6099,78.0961
12.92906798,48.195,6234,78.9557
12.9616673,48.195,6349,79.6806
12.99426662,48.195,6206,78.7782
13.02686594,48.195,6304,79.3977
13.05946526,48.195,6292,79.3221
13.09206458,48.195,6204,78.7655
13.1246639,48.195,6325,79.5299
13.15726322,48.195,6155,78.4538
13.18986254,48.195,6337,79.6053
13.22246186,48.195,6361,79.7559
13.25506118,48.195,6208,78.7909
13.2876605,48.195,6480,80.4984
13.32025982,48.195,6474,80.4612
13.35285914,48.195,6542,80.8826
13.38545846,48.195,6420,80.1249
13.41805778,48.195,6485,80.5295
13.4506571,48.195,6679,81.7251
13.48325642,48.195,6596,81.2158
13.51585574,48.195,6727,82.0183
13.54845506,48.195,6746,82.134
13.58105438,48.195,6682,81.7435
13.6136537,48.195,6722,81.9878
13.64625302,48.195,6900,83.0662
13.67885234,48.195,6883,82.9638
13.71145166,48.195,6956,83.4026
13.74405098,48.195,7102,84.2734
13.7766503,48.195,7245,85.1176
13.80924962,48.195,7462,86.3829
13.84184894,48.195,7788,88.2496
13.87444826,48.195,7904,88.9044
13.90704758,48.195,7696,87.7268
13.9396469,48.195,7790,88.261
13.97224622,48.195,7591,87.1263
14.00484554,48.195,7530,86.7756
14.03744486,48.195,7338,85.6621
14.07004418,48.195,7231,85.0353
14.1026435,48.195,7142,84.5104
14.13524282,48.195,7461,86.3771
14.16784214,48.195,7561,86.954
14.20044146,48.195,7590,87.1206
14.23304078,48.195,7415,86.1104
14.2656401,48.195,7620,87.2926
14.29823942,48.195,7558,86.9368
14.33083874,48.195,7672,87.59
14.36343806,48.195,7633,87.367
14.39603738,48.195,7690,87.6926
14.4286367,48.195,7630,87.3499
14.46123602,48.195,7810,88.3742
14.49383534,48.195,7954,89.1852
14.52643466,48.195,7919,88.9888
14.55903398,48.195,7909,88.9326
14.5916333,48.195,7813,88.3912
14.62423262,48.195,8015,89.5265
14.65683194,48.195,7909,88.9326
14.68943126,48.195,7882,88.7806
14.72203058,48.195,8010,89.4986
14.7546299,48.195,7965,89.2468
14.78722922,48.195,8043,89.6828
14.81982854,48.195,7973,89.2917
14.85242786,48.195,7956,89.1964
14.88502718,48.195,7872,88.7243
14.9176265,48.195,7751,88.0398
14.95022582,48.195,7882,88.7806
14.98282514,48.195,7943,89.1235
15.01542446,48.195,7893,88.8426
15.04802378,48.195,8026,89.5879
15.0806231,48.195,7741,87.983
15.11322242,48.195,7958,89.2076
15.14582174,48.195,7920,88.9944
15.17842106,48.195,7907,88.9213
15.21102038,48.195,7817,88.4138
15.2436197,48.195,7846,88.5776
15.27621902,48.195,7558,86.9368
15.30881834,48.195,7772,88.1589
15.34141766,48.195,7817,88.4138
15.37401698,48.195,7758,88.0795
15.4066163,48.195,7819,88.4251
15.43921562,48.195,7691,87.6983
15.47181494,48.195,7775,88.176
15.50441426,48.195,7778,88.193
15.53701358,48.195,7570,87.0057
15.5696129,48.195,7929,89.0449
15.60221222,48.195,7796,88.295
15.63481154,48.195,7662,87.5329
15.66741086,48.195,7776,88.1816
15.70001018,48.195,7833,88.5042
15.7326095,48.195,7727,87.9034
15.76520882,48.195,7775,88.176
15.79780814,48.195,7890,88.8257
15.83040746,48.195,7856,88.6341
15.86300678,48.195,7875,88.7412
15.8956061,48.195,7617,87.2754
15.92820542,48.195,7729,87.9147
15.96080474,48.195,7898,88.8707
15.99340406,48.195,7758,88.0795
16.02600338,48.195,8099,89.9944
16.0586027,48.195,8002,89.4539
16.09120202,48.195,8035,89.6382
16.12380134,48.195,7994,89.4092
16.15640066,48.195,8108,90.0444
16.18899998,48.195,8045,89.6939
16.2215993,48.195,8402,91.6624
16.25419862,48.195,8238,90.7634
16.28679794,48.195,8385,91.5696
16.31939726,48.195,8408,91.6951
16.35199658,48.195,8672,93.1236
16.3845959,48.195,9075,95.2628
16.41719522,48.195,9000,94.8683
16.44979454,48.195,9344,96.6644
16.48239386,48.195,9919,99.5942
16.51499318,48.195,10438,102.1665
16.5475925,48.195,11565,107.5407
16.58019182,48.195,12708,112.7298
16.61279114,48.195,13317,115.3993
16.64539046,48.195,14059,118.5707
16.67798978,48.195,15980,126.412
16.7105891,48.195,19114,138.2534
16.74318842,48.195,20402,142.8356
16.77578774,48.195,21588,146.9286
16.80838706,48.195,25585,159.9531
16.84098638,48.195,32565,180.4578
16.8735857,48.195,31405,177.2146
16.90618502,48.195,29860,172.8005
16.93878434,48.195,27028,164.4019
16.97138366,48.195,26750,163.5543
17.00398298,48.195,16733,129.3561
17.0365823,48.195,11410,106.8176
17.06918162,48.195,8429,91.8096
17.10178094,48.195,8128,90.1554
17.13438026,48.195,7841,88.5494
17.16697958,48.195,7772,88.1589
17.1995789,48.195,7711,87.8123
17.23217822,48.195,7755,88.0625
17.26477754,48.195,7695,87.7211
17.29737686,48.195,7647,87.4471
17.32997618,48.195,7507,86.6429
17.3625755,48.195,7183,84.7526
17.39517482,48.195,7422,86.151
17.42777414,48.195,7205,84.8823
17.46037346,48.195,7340,85.6738
17.49297278,48.195,7238,85.0764
17.5255721,48.195,7480,86.487
17.55817142,48.195,7284,85.3464
17.59077074,48.195,7529,86.7698
17.62337006,48.195,7350,85.7321
17.65596938,48.195,7395,85.9942
17.6885687,48.195,7333,85.6329
17.72116802,48.195,7369,85.8429
17.75376734,48.195,7221,84.9765
17.78636666,48.195,7418,86.1278
17.81896598,48.195,7449,86.3076
17.8515653,48.195,7451,86.3192
17.88416462,48.195,7601,87.1837
17.91676394,48.195,7733,87.9375
17.94936326,48.195,7870,88.713
17.98196258,48.195,7977,89.3141
18.0145619,48.195,7822,88.4421
18.04716122,48.195,8118,90.0999
18.07976054,48.195,8221,90.6697
18.11235986,48.195,7999,89.4371
18.14495918,48.195,7864,88.6792
18.1775585,48.195,7791,88.2666
18.21015782,48.195,8839,94.016
18.24275714,48.195,9721,98.5951
18.27535646,48.195,10231,101.1484
18.30795578,48.195,10946,104.6231
18.3405551,48.195,11887,109.0275
18.37315442,48.195,12267,110.7565
18.40575374,48.195,10968,104.7282
18.43835306,48.195,9293,96.4002
18.47095238,48.195,7834,88.5099
18.5035517,48.195,7383,85.9244
18.53615102,48.195,7555,86.9195
18.56875034,48.195,7509,86.6545
18.60134966,48.195,7417,86.122
18.63394898,48.195,7319,85.5512
18.6665483,48.195,7190,84.7939
18.69914762,48.195,7195,84.8233
18.73174694,48.195,7388,85.9535
18.76434626,48.195,7313,85.5161
18.79694558,48.195,7299,85.4342
18.8295449,48.195,7502,86.6141
18.86214422,48.195,7431,86.2032
18.89474354,48.195,7398,86.0116
18.92734286,48.195,7626,87.327
18.95994218,48.195,7605,87.2067
18.9925415,48.195,7506,86.6372
19.02514082,48.195,7527,86.7583
19.05774014,48.195,7357,85.773
19.09033946,48.195,7317,85.5395
19.12293878,48.195,7496,86.5794
19.1555381,48.195,7439,86.2496
19.18813742,48.195,7392,85.9767
19.22073674,48.195,7490,86.5448
19.25333606,48.195,7435,86.2264
19.28593538,48.195,7438,86.2438
19.3185347,48.195,7788,88.2496
19.35113402,48.195,7795,88.2893
19.38373334,48.195,7954,89.1852
19.41633266,48.195,7944,89.1291
19.44893198,48.195,8049,89.7162
19.4815313,48.195,8076,89.8666
19.51413062,48.195,8373,91.5041
19.54672994,48.195,8002,89.4539
19.57932926,48.195,7986,89.3644
19.61192858,48.195,8127,90.1499
19.6445279,48.195,8816,93.8936
19.67712722,48.195,9139,95.5981
19.70972654,48.195,9960,99.7998
19.74232586,48.195,10253,101.2571
19.77492518,48.195,9775,98.8686
19.8075245,48.195,8514,92.2713
19.84012382,48.195,7995,89.4148
19.87272314,48.195,7463,86.3887
19.90532246,48.195,7531,86.7813
19.93792178,48.195,7452,86.325
19.9705211,48.195,7673,87.5957
20.00312042,48.195,7620,87.2926
20.03571974,48.195,7599,87.1722
20.06831906,48.195,7724,87.8863
20.10091838,48.195,7816,88.4081
20.1335177,48.195,7756,88.0682
20.16611702,48.195,7773,88.1646
20.19871634,48.195,7766,88.1249
20.23131566,48.195,7839,88.5381
20.26391498,48.195,7860,88.6566
20.2965143,48.195,8020,89.5545
20.32911362,48.195,7843,88.5607
20.36171294,48.195,7965,89.2468
20.39431226,48.195,7984,89.3532
20.42691158,48.195,8056,89.7552
20.4595109,48.195,7852,88.6115
20.49211022,48.195,7949,89.1572
20.52470954,48.195,8094,89.9667
20.55730886,48.195,7888,88.8144
20.58990818,48.195,7819,88.4251
20.6225075,48.195,7872,88.7243
20.65510682,48.195,7923,89.0112
20.68770614,48.195,7939,89.1011
20.72030546,48.195,7822,88.4421
20.75290478,48.195,7976,89.3085
20.7855041,48.195,7997,89.4259
20.81810342,48.195,8084,89.9111
20.85070274,48.195,8045,89.6939
20.88330206,48.195,8233,90.7359
20.91590138,48.195,8723,93.397
20.9485007,48.195,8930,94.4987
20.98110002,48.195,9054,95.1525
21.01369934,48.195,9478,97.355
21.04629866,48.195,9216,96
21.07889798,48.195,8503,92.2117
21.1114973,48.195,8045,89.6939
21.14409662,48.195,8066,89.8109
21.17669594,48.195,7915,88.9663
21.20929526,48.195,7879,88.7637
21.24189458,48.195,7783,88.2213
21.2744939,48.195,7855,88.6284
21.30709322,48.195,7977,89.3141
21.33969254,48.195,7994,89.4092
21.37229186,48.195,8096,89.9778
21.40489118,48.195,8091,89.95
21.4374905,48.195,8035,89.6382
21.47008982,48.195,8291,91.0549
21.50268914,48.195,8202,90.5649
21.53528846,48.195,8369,91.4822
21.56788778,48.195,8459,91.9728
21.6004871,48.195,8459,91.9728
21.63308642,48.195,8554,92.4878
21.66568574,48.195,8581,92.6337
21.69828506,48.195,8849,94.0691
21.73088438,48.195,8798,93.7977
21.7634837,48.195,9080,95.289
21.79608302,48.195,9140,95.6033
21.82868234,48.195,9088,95.331
21.86128166,48.195,9428,97.0979
21.89388098,48.195,9645,98.209
21.9264803,48.195,9593,97.9439
21.95907962,48.195,9764,98.813
21.99167894,48.195,9925,99.6243
22.02427826,48.195,10257,101.2768
22.05687758,48.195,10383,101.897
22.0894769,48.195,10467,102.3084
22.12207622,48.195,10636,103.131
22.15467554,48.195,10931,104.5514
22.18727486,48.195,11034,105.0428
22.21987418,48.195,11431,106.9159
22.2524735,48.195,11454,107.0234
22.28507282,48.195,11661,107.9861
22.31767214,48.195,12119,110.0863
22.35027146,48.195,11927,109.2108
22.38287078,48.195,12209,110.4943
22.4154701,48.195,12520,111.8928
22.44806942,48.195,12473,111.6826
22.48066874,48.195,12743,112.8849
22.51326806,48.195,13016,114.0877
22.54586738,48.195,12969,113.8815
22.5784667,48.195,13159,114.7127
22.61106602,48.195,12984,113.9474
22.64366534,48.195,12910,113.6222
22.67626466,48.195,12756,112.9425
22.70886398,48.195,12629,112.3788
22.7414633,48.195,12487,111.7452
22.77406262,48.195,12640,112.4278
22.80666194,48.195,12415,111.4226
22.83926126,48.195,12100,110
22.87186058,48.195,12278,110.8061
22.9044599,48.195,12053,109.7862
22.93705922,48.195,11852,108.8669
22.96965854,48.195,11961,109.3664
23.00225786,48.195,11705,108.1896
23.03485718,48.195,11765,108.4666
23.0674565,48.195,11749,108.3928
23.10005582,48.195,11173,105.7024
23.13265514,48.195,11117,105.4372
23.16525446,48.195,10562,102.7716
23.19785378,48.195,10814,103.9904
23.2304531,48.195,11132,105.5083
23.26305242,48.195,10354,101.7546
23.29565174,48.195,10198,100.9851
23.32825106,48.195,9850,99.2472
23.36085038,48.195,9544,97.6934
23.3934497,48.195,9440,97.1597
23.42604902,48.195,9508,97.509
23.45864834,48.195,9946,99.7296
23.49124766,48.195,10504,102.489
23.52384698,48.195,10359,101.7792
23.5564463,48.195,10235,101.1682
23.58904562,48.195,10077,100.3843
23.62164494,48.195,9646,98.2141
23.65424426,48.195,10930,104.5466
23.68684358,48.195,13371,115.633
23.7194429,48.195,12860,113.4019
23.75204222,48.195,12025,109.6586
23.78464154,48.195,12577,112.1472
23.81724086,48.195,17250,131.3393
23.84984018,48.195,20173,142.0317
23.8824395,48.195,19515,139.6961
23.91503882,48.195,13808,117.5074
23.94763814,48.195,10655,103.2231
23.98023746,48.195,7571,87.0115
24.01283678,48.195,7424,86.1626
24.0454361,48.195,7229,85.0235
24.07803542,48.195,7054,83.9881
24.11063474,48.195,7234,85.0529
24.14323406,48.195,7079,84.1368
24.17583338,48.195,7090,84.2021
24.2084327,48.195,6943,83.3247
24.24103202,48.195,6921,83.1925
24.27363134,48.195,6970,83.4865
24.30623066,48.195,6871,82.8915
24.33882998,48.195,6817,82.5651
24.3714293,48.195,6916,83.1625
24.40402862,48.195,6817,82.5651
24.43662794,48.195,6890,83.006
24.46922726,48.195,6739,82.0914
24.50182658,48.195,6571,81.0617
24.5344259,48.195,6791,82.4075
24.56702522,48.195,6680,81.7313
24.59962454,48.195,6621,81.3695
24.63222386,48.195,6667,81.6517
24.66482318,48.195,6615,81.3327
24.6974225,48.195,6730,82.0366
24.73002182,48.195,6719,81.9695
24.76262114,48.195,6494,80.5854
24.79522046,48.195,6662,81.6211
24.82781978,48.195,6528,80.796
24.8604191,48.195,6436,80.2247
24.89301842,48.195,6601,81.2465
24.92561774,48.195,6340,79.6241
24.95821706,48.195,6530,80.8084
24.99081638,48.195,6393,79.9562
25.0234157,48.195,6525,80.7775
25.05601502,48.195,6441,80.2558
25.08861434,48.195,6520,80.7465
25.12121366,48.195,6393,79.9562
25.15381298,48.195,6292,79.3221
25.1864123,48.195,6412,80.075
25.21901162,48.195,6561,81
25.25161094,48.195,6605,81.2712
25.28421026,48.195,6444,80.2745
25.31680958,48.195,6585,81.148
25.3494089,48.195,6699,81.8474
25.38200822,48.195,6555,80.963
25.41460754,48.195,6742,82.1097
25.44720686,48.195,6624,81.388
25.47980618,48.195,6704,81.878
25.5124055,48.195,6652,81.5598
25.54500482,48.195,6793,82.4197
25.57760414,48.195,6865,82.8553
25.61020346,48.195,6664,81.6333
25.64280278,48.195,7129,84.4334
25.6754021,48.195,7434,86.2206
25.70800142,48.195,7706,87.7838
25.74060074,48.195,8045,89.6939
25.77320006,48.195,9524,97.591
25.80579938,48.195,10323,101.6022
25.8383987,48.195,10381,101.8872
25.87099802,48.195,9443,97.1751
25.90359734,48.195,8200,90.5539
25.93619666,48.195,7058,84.0119
25.96879598,48.195,6384,79.8999
26.0013953,48.195,6435,80.2185
26.03399462,48.195,6510,80.6846
26.06659394,48.195,6882,82.9578
26.09919326,48.195,7009,83.7198
26.13179258,48.195,7601,87.1837
26.1643919,48.195,7798,88.3063
26.19699122,48.195,7636,87.3842
26.22959054,48.195,7186,84.7703
26.26218986,48.195,6947,83.3487
26.29478918,48.195,6577,81.0987
26.3273885,48.195,6368,79.7997
26.35998782,48.195,6169,78.543
26.39258714,48.195,5947,77.1168
26.42518646,48.195,5908,76.8635
26.45778578,48.195,5865,76.5833
26.4903851,48.195,5784,76.0526
26.52298442,48.195,5864,76.5768
26.55558374,48.195,5947,77.1168
26.58818306,48.195,5648,75.1532
26.62078238,48.195,5747,75.809
26.6533817,48.195,5780,76.0263
26.68598102,48.195,5644,75.1266
26.71858034,48.195,5715,75.5976
26.75117966,48.195,5708,75.5513
26.78377898,48.195,5742,75.776
26.8163783,48.195,5831,76.361
26.84897762,48.195,5694,75.4586
26.88157694,48.195,5672,75.3127
26.91417626,48.195,5710,75.5645
26.94677558,48.195,5672,75.3127
26.9793749,48.195,5577,74.6793
27.01197422,48.195,5709,75.5579
27.04457354,48.195,5520,74.2967
27.07717286,48.195,5592,74.7797
27.10977218,48.195,5641,75.1066
27.1423715,48.195,5722,75.6439
27.17497082,48.195,5612,74.9133
27.20757014,48.195,5579,74.6927
27.24016946,48.195,5732,75.71
27.27276878,48.195,5646,75.1399
27.3053681,48.195,5783,76.046
27.33796742,48.195,5784,76.0526
27.37056674,48.195,5903,76.831
27.40316606,48.195,5689,75.4255
27.43576538,48.195,5893,76.7659
27.4683647,48.195,5826,76.3282
27.50096402,48.195,5884,76.7072
27.53356334,48.195,5869,76.6094
27.56616266,48.195,6051,77.7882
27.59876198,48.195,6007,77.5048
27.6313613,48.195,6076,77.9487
27.66396062,48.195,6201,78.7464
27.69655994,48.195,6358,79.7371
27.72915926,48.195,6645,81.5169
27.76175858,48.195,7031,83.8511
27.7943579,48.195,7956,89.1964
27.82695722,48.195,8120,90.111
27.85955654,48.195,8321,91.2195
27.89215586,48.195,9705,98.514
27.92475518,48.195,11023,104.9905
27.9573545,48.195,12777,113.0354
27.98995382,48.195,13308,115.3603
28.02255314,48.195,11899,109.0825
28.05515246,48.195,11369,106.6255
28.08775178,48.195,9161,95.7131
28.1203511,48.195,7776,88.1816
28.15295042,48.195,7241,85.0941
28.18554974,48.195,6343,79.643
28.21814906,48.195,6006,77.4984
28.25074838,48.195,5686,75.4056
28.2833477,48.195,5676,75.3392
28.31594702,48.195,5559,74.5587
28.34854634,48.195,5658,75.2197
28.38114566,48.195,5562,74.5788
28.41374498,48.195,5688,75.4188
28.4463443,48.195,5685,75.3989
28.47894362,48.195,5701,75.505
28.51154294,48.195,5737,75.743
28.54414226,48.195,5890,76.7463
28.57674158,48.195,5853,76.5049
28.6093409,48.195,5686,75.4056
28.64194022,48.195,5753,75.8485
28.67453954,48.195,5555,74.5319
28.70713886,48.195,5555,74.5319
28.73973818,48.195,5605,74.8665
28.7723375,48.195,5554,74.5252
28.80493682,48.195,5513,74.2496
28.83753614,48.195,5499,74.1552
28.87013546,48.195,5570,74.6324
28.90273478,48.195,5485,74.0608
28.9353341,48.195,5411,73.5595
28.96793342,48.195,5421,73.6274
29.00053274,48.195,5420,73.6206
29.03313206,48.195,5345,73.1095
29.06573138,48.195,5463,73.9121
29.0983307,48.195,5218,72.2357
29.13093002,48.195,5224,72.2772
29.16352934,48.195,5160,71.8331
29.19612866,48.195,5325,72.9726
29.22872798,48.195,5216,72.2219
29.2613273,48.195,5167,71.8818
29.29392662,48.195,5386,73.3894
29.32652594,48.195,5290,72.7324
29.35912526,48.195,5407,73.5323
29.39172458,48.195,5236,72.3602
29.4243239,48.195,5405,73.5187
29.45692322,48.195,5451,73.8309
29.48952254,48.195,5418,73.6071
29.52212186,48.195,5453,73.8444
29.55472118,48.195,5494,74.1215
29.5873205,48.195,5289,72.7255
29.61991982,48.195,5362,73.2257
29.65251914,48.195,5452,73.8377
29.68511846,48.195,5540,74.4312
29.71771778,48.195,5279,72.6567
29.7503171,48.195,5396,73.4575
29.78291642,48.195,5308,72.856
29.81551574,48.195,5331,73.0137
29.84811506,48.195,5300,72.8011
29.88071438,48.195,5165,71.8679
29.9133137,48.195,5139,71.6868
29.94591302,48.195,5076,71.2461
29.97851234,48.195,5183,71.9931
30.01111166,48.195,4997,70.6895
30.04371098,48.195,4997,70.6895
30.0763103,48.195,5065,71.1688
30.10890962,48.195,5002,70.7248
30.14150894,48.195,5154,71.7914
30.17410826,48.195,4976,70.5408
30.20670758,48.195,4905,70.0357
30.2393069,48.195,5031,70.9295
30.27190622,48.195,4967,70.4769
30.30450554,48.195,5074,71.232
30.33710486,48.195,4980,70.5691
30.36970418,48.195,4899,69.9929
30.4023035,48.195,4986,70.6116
30.43490282,48.195,4975,70.5337
30.46750214,48.195,4959,70.4202
30.50010146,48.195,4994,70.6682
30.53270078,48.195,4985,70.6045
30.5653001,48.195,4954,70.3847
30.59789942,48.195,4972,70.5124
30.63049874,48.195,5026,70.8943
30.66309806,48.195,4938,70.2709
30.69569738,48.195,4979,70.562
30.7282967,48.195,5061,71.1407
30.76089602,48.195,4986,70.6116
30.79349534,48.195,4956,70.3989
30.82609466,48.195,4944,70.3136
30.85869398,48.195,5016,70.8237
30.8912933,48.195,5008,70.7672
30.92389262,48.195,4939,70.278
30.95649194,48.195,4872,69.7997
30.98909126,48.195,4923,70.1641
31.02169058,48.195,5055,71.0985
31.0542899,48.195,4999,70.7036
31.08688922,48.195,4907,70.05
31.11948854,48.195,4920,70.1427
31.15208786,48.195,5043,71.0141
31.18468718,48.195,5048,71.0493
31.2172865,48.195,5047,71.0422
31.24988582,48.195,5065,71.1688
31.28248514,48.195,5098,71.4003
31.31508446,48.195,5218,72.2357
31.34768378,48.195,5244,72.4155
31.3802831,48.195,5370,73.2803
31.41288242,48.195,5428,73.675
31.44548174,48.195,5550,74.4983
31.47808106,48.195,5881,76.6877
31.51068038,48.195,6066,77.8845
31.5432797,48.195,6194,78.702
31.57587902,48.195,6371,79.8185
31.60847834,48.195,6139,78.3518
31.64107766,48.195,6142,78.3709
31.67367698,48.195,6124,78.256
31.7062763,48.195,6146,78.3964
31.73887562,48.195,6116,78.2049
31.77147494,48.195,6087,78.0192
31.80407426,48.195,5872,76.629
31.83667358,48.195,5665,75.2662
31.8692729,48.195,5721,75.6373
31.90187222,48.195,5415,73.5867
31.93447154,48.195,5353,73.1642
31.96707086,48.195,5260,72.5259
31.99967018,48.195,5192,72.0555
32.0322695,48.195,5238,72.374
32.06486882,48.195,5130,71.624
32.09746814,48.195,4994,70.6682
32.13006746,48.195,4824,69.455
32.16266678,48.195,4997,70.6895
32.1952661,48.195,5100,71.4143
32.22786542,48.195,4974,70.5266
32.26046474,48.195,4778,69.1231
32.29306406,48.195,4753,68.942
32.32566338,48.195,4649,68.1836
32.3582627,48.195,4668,68.3228
32.39086202,48.195,4857,69.6922
32.42346134,48.195,4932,70.2282
32.45606066,48.195,4743,68.8694
32.48865998,48.195,4883,69.8785
32.5212593,48.195,5031,70.9295
32.55385862,48.195,4730,68.775
32.58645794,48.195,4918,70.1285
32.61905726,48.195,4915,70.1071
32.65165658,48.195,4879,69.8498
32.6842559,48.195,5047,71.0422
32.71685522,48.195,4971,70.5053
32.74945454,48.195,4851,69.6491
32.78205386,48.195,5025,70.8872
32.81465318,48.195,5154,71.7914
32.8472525,48.195,5265,72.5603
32.87985182,48.195,5092,71.3583
32.91245114,48.195,4924,70.1712
32.94505046,48.195,4863,69.7352
32.97764978,48.195,4679,68.4032
33.0102491,48.195,4715,68.6659
33.04284842,48.195,4704,68.5857
33.07544774,48.195,4804,69.3109
33.10804706,48.195,4750,68.9202
33.14064638,48.195,4751,68.9275
33.1732457,48.195,4968,70.484
33.20584502,48.195,4744,68.8767
33.23844434,48.195,4743,68.8694
33.27104366,48.195,4827,69.4766
33.30364298,48.195,4871,69.7925
33.3362423,48.195,4869,69.7782
33.36884162,48.195,4952,70.3704
33.40144094,48.195,5018,70.8378
33.43404026,48.195,5015,70.8167
33.46663958,48.195,5197,72.0902
33.4992389,48.195,5266,72.5672
33.53183822,48.195,5371,73.2871
33.56443754,48.195,5531,74.3707
33.59703686,48.195,5506,74.2024
33.62963618,48.195,5625,75
33.6622355,48.195,5989,77.3886
33.69483482,48.195,5851,76.4918
33.72743414,48.195,6200,78.7401
33.76003346,48.195,6399,79.9937
33.79263278,48.195,6814,82.547
33.8252321,48.195,6950,83.3667
33.85783142,48.195,7183,84.7526
33.89043074,48.195,7357,85.773
33.92303006,48.195,8416,91.7388
33.95562938,48.195,9092,95.352
33.9882287,48.195,9624,98.102
34.02082802,48.195,9579,97.8724
34.05342734,48.195,8624,92.8655
34.08602666,48.195,8027,89.5935
34.11862598,48.195,7615,87.264
34.1512253,48.195,8170,90.3881
34.18382462,48.195,7556,86.9253
34.21642394,48.195,8102,90.0111
34.24902326,48.195,10301,101.4938
34.28162258,48.195,9292,96.395
34.3142219,48.195,10357,101.7693
34.34682122,48.195,9201,95.9218
34.37942054,48.195,7844,88.5664
34.41201986,48.195,6873,82.9036
34.44461918,48.195,6026,77.6273
34.4772185,48.195,5477,74.0068
34.50981782,48.195,4823,69.4478
34.54241714,48.195,4975,70.5337
34.57501646,48.195,4951,70.3633
34.60761578,48.195,4816,69.3974
34.6402151,48.195,4838,69.5557
34.67281442,48.195,4714,68.6586
34.70541374,48.195,4537,67.3573
34.73801306,48.195,4623,67.9926
34.77061238,48.195,4627,68.0221
34.8032117,48.195,4537,67.3573
34.83581102,48.195,4652,68.2056
34.86841034,48.195,4404,66.3626
34.90100966,48.195,4579,67.6683
34.93360898,48.195,4549,67.4463
34.9662083,48.195,4473,66.8805
34.99880762,48.195,4543,67.4018
35.03140694,48.195,4362,66.0454
35.06400626,48.195,4429,66.5507
35.09660558,48.195,4397,66.3099
35.1292049,48.195,4443,66.6558
35.16180422,48.195,4442,66.6483
35.19440354,48.195,4406,66.3777
35.22700286,48.195,4358,66.0151
35.25960218,48.195,4350,65.9545
35.2922015,48.195,4364,66.0606
35.32480082,48.195,4317,65.7039
35.35740014,48.195,4373,66.1287
35.38999946,48.195,4450,66.7083
35.42259878,48.195,4315,65.6887
35.4551981,48.195,4312,65.6658
35.48779742,48.195,4435,66.5958
35.52039674,48.195,4441,66.6408
35.55299606,48.195,4347,65.9318
35.58559538,48.195,4404,66.3626
35.6181947,48.195,4629,68.0368
35.65079402,48.195,4835,69.5342
35.68339334,48.195,4660,68.2642
35.71599266,48.195,4824,69.455
35.74859198,48.195,5181,71.9792
35.7811913,48.195,4964,70.4557
35.81379062,48.195,4960,70.4273
35.84638994,48.195,4991,70.647
35.87898926,48.195,4971,70.5053
35.91158858,48.195,5160,71.8331
35.9441879,48.195,5992,77.408
35.97678722,48.195,7054,83.9881
36.00938654,48.195,6170,78.5493
36.04198586,48.195,6658,81.5966
36.07458518,48.195,9475,97.3396
36.1071845,48.195,10397,101.9657
36.13978382,48.195,9960,99.7998
36.17238314,48.195,8166,90.3659
36.20498246,48.195,7470,86.4292
36.23758178,48.195,6689,81.7863
36.2701811,48.195,5376,73.3212
36.30278042,48.195,4600,67.8233
36.33537974,48.195,4433,66.5808
36.36797906,48.195,4343,65.9014
36.40057838,48.195,4357,66.0076
36.4331777,48.195,4415,66.4455
36.46577702,48.195,4487,66.9851
36.49837634,48.195,4266,65.3146
36.53097566,48.195,4472,66.873
36.56357498,48.195,4653,68.2129
36.5961743,48.195,5171,71.9097
36.62877362,48.195,5181,71.9792
36.66137294,48.195,4879,69.8498
36.69397226,48.195,4817,69.4046
36.72657158,48.195,4891,69.9357
36.7591709,48.195,4483,66.9552
36.79177022,48.195,4465,66.8207
36.82436954,48.195,4379,66.174
36.85696886,48.195,4345,65.9166
36.88956818,48.195,4154,64.4515
36.9221675,48.195,4166,64.5446
36.95476682,48.195,4249,65.1844
36.98736614,48.195,4197,64.7843
37.01996546,48.195,4151,64.4283
37.05256478,48.195,4209,64.8768
37.0851641,48.195,4091,63.9609
37.11776342,48.195,4177,64.6297
37.15036274,48.195,4074,63.8279
37.18296206,48.195,4209,64.8768
37.21556138,48.195,4194,64.7611
37.2481607,48.195,4076,63.8436
37.28076002,48.195,4225,65
37.31335934,48.195,4207,64.8614
37.34595866,48.195,4142,64.3584
37.37855798,48.195,4203,64.8305
37.4111573,48.195,4106,64.0781
37.44375662,48.195,4181,64.6607
37.47635594,48.195,4249,65.1844
37.50895526,48.195,4258,65.2534
37.54155458,48.195,4312,65.6658
37.5741539,48.195,4458,66.7683
37.60675322,48.195,5221,72.2565
37.63935254,48.195,5777,76.0066
37.67195186,48.195,5743,75.7826
37.70455118,48.195,5803,76.1774
37.7371505,48.195,5759,75.8881
37.76974982,48.195,5794,76.1183
37.80234914,48.195,5698,75.4851
37.83494846,48.195,5289,72.7255
37.86754778,48.195,5062,71.1477
37.9001471,48.195,5067,71.1829
37.93274642,48.195,4667,68.3154
37.96534574,48.195,4532,67.3201
37.99794506,48.195,4477,66.9104
38.03054438,48.195,4533,67.3276
38.0631437,48.195,4221,64.9692
38.09574302,48.195,4160,64.4981
38.12834234,48.195,4146,64.3894
38.16094166,48.195,4134,64.2962
38.19354098,48.195,4111,64.1171
38.2261403,48.195,4214,64.9153
38.25873962,48.195,4054,63.671
38.29133894,48.195,4134,64.2962
38.32393826,48.195,4007,63.3009
38.35653758,48.195,4210,64.8845
38.3891369,48.195,4024,63.435
38.42173622,48.195,4190,64.7302
38.45433554,48.195,4008,63.3088
38.48693486,48.195,4042,63.5767
38.51953418,48.195,4093,63.9766
38.5521335,48.195,4136,64.3117
38.58473282,48.195,4070,63.7966
38.61733214,48.195,4139,64.3351
38.64993146,48.195,4085,63.914
38.68253078,48.195,4160,64.4981
38.7151301,48.195,4112,64.1249
38.74772942,48.195,4168,64.56
38.78032874,48.195,4139,64.3351
38.81292806,48.195,4058,63.7024
38.84552738,48.195,4202,64.8228
38.8781267,48.195,4157,64.4748
38.91072602,48.195,4197,64.7843
38.94332534,48.195,4336,65.8483
38.97592466,48.195,4451,66.7158
39.00852398,48.195,4490,67.0075
39.0411233,48.195,4667,68.3154
39.07372262,48.195,4543,67.4018
39.10632194,48.195,4488,66.9925
39.13892126,48.195,4556,67.4981
39.17152058,48.195,4654,68.2202
39.2041199,48.195,4685,68.4471
39.23671922,48.195,4667,68.3154
39.26931854,48.195,4778,69.1231
39.30191786,48.195,4859,69.7065
39.33451718,48.195,5255,72.4914
39.3671165,48.195,5403,73.5051
39.39971582,48.195,4883,69.8785
39.43231514,48.195,5046,71.0352
39.46491446,48.195,5864,76.5768
39.49751378,48.195,5545,74.4648
39.5301131,48.195,6045,77.7496
39.56271242,48.195,6747,82.1401
39.59531174,48.195,7128,84.4275
39.62791106,48.195,6704,81.878
39.66051038,48.195,5583,74.7195
39.6931097,48.195,5345,73.1095
39.72570902,48.195,5074,71.232
39.75830834,48.195,4444,66.6633
39.79090766,48.195,4133,64.2884
39.82350698,48.195,4339,65.8711
39.8561063,48.195,4459,66.7757
39.88870562,48.195,4725,68.7386
39.92130494,48.195,4721,68.7095
39.95390426,48.195,4449,66.7008
39.98650358,48.195,4914,70.0999
40.0191029,48.195,5507,74.2092
40.05170222,48.195,5815,76.2561
40.08430154,48.195,5855,76.518
40.11690086,48.195,6621,81.3695
40.14950018,48.195,7522,86.7295
40.1820995,48.195,8255,90.857
40.21469882,48.195,7939,89.1011
40.24729814,48.195,7147,84.5399
40.27989746,48.195,7234,85.0529
40.31249678,48.195,6539,80.8641
40.3450961,48.195,5524,74.3236
40.37769542,48.195,5226,72.2911
40.41029474,48.195,4963,70.4486
40.44289406,48.195,4585,67.7126
40.47549338,48.195,4859,69.7065
40.5080927,48.195,5247,72.4362
40.54069202,48.195,5504,74.1889
40.57329134,48.195,5432,73.7021
40.60589066,48.195,4871,69.7925
40.63848998,48.195,5226,72.2911
40.6710893,48.195,5137,71.6729
40.70368862,48.195,5046,71.0352
40.73628794,48.195,5075,71.239
40.76888726,48.195,4435,66.5958
40.80148658,48.195,4398,66.3174
40.8340859,48.195,4532,67.3201
40.86668522,48.195,4046,63.6082
40.89928454,48.195,3961,62.9365
40.93188386,48.195,3816,61.7738
40.96448318,48.195,3883,62.3137
40.9970825,48.195,3759,61.3107
41.02968182,48.195,3942,62.7853
41.06228114,48.195,3862,62.145
41.09488046,48.195,3842,61.9839
41.12747978,48.195,3770,61.4003
41.1600791,48.195,3765,61.3596
41.19267842,48.195,3819,61.7981
41.22527774,48.195,3887,62.3458
41.25787706,48.195,3690,60.7454
41.29047638,48.195,3794,61.5955
41.3230757,48.195,3690,60.7454
41.35567502,48.195,3772,61.4166
41.38827434,48.195,3790,61.563
41.42087366,48.195,3849,62.0403
41.45347298,48.195,3822,61.8223
41.4860723,48.195,3858,62.1128
41.51867162,48.195,3944,62.8013
41.55127094,48.195,3947,62.8252
41.58387026,48.195,3923,62.6339
41.61646958,48.195,3766,61.3677
41.6490689,48.195,3918,62.5939
41.68166822,48.195,3797,61.6198
41.71426754,48.195,3873,62.2334
41.74686686,48.195,3913,62.554
41.77946618,48.195,4047,63.616
41.8120655,48.195,4070,63.7966
41.84466482,48.195,4036,63.5295
41.87726414,48.195,3957,62.9047
41.90986346,48.195,3848,62.0322
41.94246278,48.195,3912,62.546
41.9750621,48.195,3888,62.3538
42.00766142,48.195,3820,61.8061
42.04026074,48.195,3954,62.8808
42.07286006,48.195,3893,62.3939
42.10545938,48.195,3920,62.6099
42.1380587,48.195,3984,63.1189
42.17065802,48.195,3884,62.3217
42.20325734,48.195,3942,62.7853
42.23585666,48.195,3874,62.2415
42.26845598,48.195,3883,62.3137
42.3010553,48.195,3852,62.0645
42.33365462,48.195,3785,61.5224
42.36625394,48.195,3851,62.0564
42.39885326,48.195,3731,61.0819
42.43145258,48.195,3878,62.2736
42.4640519,48.195,3853,62.0725
42.49665122,48.195,3944,62.8013
42.52925054,48.195,3816,61.7738
42.56184986,48.195,4034,63.5138
42.59444918,48.195,3926,62.6578
42.6270485,48.195,4034,63.5138
42.65964782,48.195,4092,63.9687
42.69224714,48.195,4079,63.867
42.72484646,48.195,4136,64.3117
42.75744578,48.195,4286,65.4675
42.7900451,48.195,4422,66.4981
42.82264442,48.195,4278,65.4064
42.85524374,48.195,4090,63.9531
42.88784306,48.195,4083,63.8984
42.92044238,48.195,4082,63.8905
42.9530417,48.195,4015,63.364
42.98564102,48.195,3865,62.1691
43.01824034,48.195,3728,61.0574
43.05083966,48.195,3799,61.636
43.08343898,48.195,3811,61.7333
43.1160383,48.195,3948,62.8331
43.14863762,48.195,3963,62.9524
43.18123694,48.195,3873,62.2334
43.21383626,48.195,3701,60.8358
43.24643558,48.195,3764,61.3514
43.2790349,48.195,3851,62.0564
43.31163422,48.195,4176,64.622
43.34423354,48.195,4271,65.3529
43.37683286,48.195,3955,62.8888
43.40943218,48.195,4213,64.9076
43.4420315,48.195,4258,65.2534
43.47463082,48.195,4133,64.2884
43.50723014,48.195,3811,61.7333
43.53982946,48.195,3792,61.5792
43.57242878,48.195,3928,62.6738
43.6050281,48.195,3793,61.5873
43.63762742,48.195,3927,62.6658
43.67022674,48.195,4104,64.0625
43.70282606,48.195,4038,63.5453
43.73542538,48.195,4018,63.3877
43.7680247,48.195,4227,65.0154
43.80062402,48.195,4139,64.3351
43.83322334,48.195,4216,64.9307
43.86582266,48.195,4249,65.1844
43.89842198,48.195,4181,64.6607
43.9310213,48.195,4040,63.561
43.96362062,48.195,4034,63.5138
43.99621994,48.195,4098,64.0156
44.02881926,48.195,3891,62.3779
44.06141858,48.195,3827,61.8628
44.0940179,48.195,3689,60.7371
44.12661722,48.195,3576,59.7997
44.15921654,48.195,3634,60.2827
44.19181586,48.195,3560,59.6657
44.22441518,48.195,3417,58.4551
44.2570145,48.195,3546,59.5483
44.28961382,48.195,3527,59.3886
44.32221314,48.195,3471,58.9152
44.35481246,48.195,3459,58.8133
44.38741178,48.195,3541,59.5063
44.4200111,48.195,3554,59.6154
44.45261042,48.195,3502,59.1777
44.48520974,48.195,3506,59.2115
44.51780906,48.195,3498,59.1439
44.55040838,48.195,3560,59.6657
44.5830077,48.195,3604,60.0333
44.61560702,48.195,3474,58.9406
44.64820634,48.195,3509,59.2368
44.68080566,48.195,3630,60.2495
44.71340498,48.195,3530,59.4138
44.7460043,48.195,3594,59.95
44.77860362,48.195,3615,60.1249
44.81120294,48.195,3483,59.0169
44.84380226,48.195,3480,58.9915
44.87640158,48.195,3551,59.5903
44.9090009,48.195,3436,58.6174
44.94160022,48.195,3421,58.4893
44.97419954,48.195,3511,59.2537
45.00679886,48.195,3305,57.4891
45.03939818,48.195,3444,58.6856
45.0719975,48.195,3465,58.8643
45.10459682,48.195,3442,58.6686
45.13719614,48.195,3352,57.8965
45.16979546,48.195,3463,58.8473
45.20239478,48.195,3369,58.0431
45.2349941,48.195,3339,57.7841
45.26759342,48.195,3289,57.3498
45.30019274,48.195,3311,57.5413
45.33279206,48.195,3336,57.7581
45.36539138,48.195,3375,58.0948
45.3979907,48.195,3375,58.0948
45.43059002,48.195,3448,58.7197
45.46318934,48.195,3414,58.4294
45.49578866,48.195,3460,58.8218
45.52838798,48.195,3411,58.4038
45.5609873,48.195,3472,58.9237
45.59358662,48.195,3491,59.0847
45.62618594,48.195,3431,58.5747
45.65878526,48.195,3594,59.95
45.69138458,48.195,3520,59.3296
45.7239839,48.195,3482,59.0085
45.75658322,48.195,3483,59.0169
45.78918254,48.195,3460,58.8218
45.82178186,48.195,3496,59.127
45.85438118,48.195,3522,59.3464
45.8869805,48.195,3658,60.4814
45.91957982,48.195,3734,61.1065
45.95217914,48.195,3696,60.7947
45.98477846,48.195,3483,59.0169
46.01737778,48.195,3615,60.1249
46.0499771,48.195,3611,60.0916
46.08257642,48.195,3558,59.649
46.11517574,48.195,3416,58.4466
46.14777506,48.195,3433,58.5918
46.18037438,48.195,3430,58.5662
46.2129737,48.195,3467,58.8812
46.24557302,48.195,3407,58.3695
46.27817234,48.195,3389,58.2151
46.31077166,48.195,3425,58.5235
46.34337098,48.195,3508,59.2284
46.3759703,48.195,3361,57.9741
46.40856962,48.195,3453,58.7622
46.44116894,48.195,3301,57.4543
46.47376826,48.195,3270,57.1839
46.50636758,48.195,3179,56.3826
46.5389669,48.195,3287,57.3324
46.57156622,48.195,3354,57.9137
46.60416554,48.195,3333,57.7321
46.63676486,48.195,3362,57.9828
46.66936418,48.195,3317,57.5934
46.7019635,48.195,3450,58.7367
46.73456282,48.195,3359,57.9569
46.76716214,48.195,3483,59.0169
46.79976146,48.195,3406,58.3609
46.83236078,48.195,3378,58.1206
46.8649601,48.195,3388,58.2065
46.89755942,48.195,3475,58.9491
46.93015874,48.195,3772,61.4166
46.96275806,48.195,3856,62.0967
46.99535738,48.195,3684,60.696
47.0279567,48.195,3702,60.8441
47.06055602,48.195,3813,61.7495
47.09315534,48.195,3862,62.145
47.12575466,48.195,3844,62
47.15835398,48.195,3953,62.8729
47.1909533,48.195,4348,65.9394
47.22355262,48.195,4854,69.6707
47.25615194,48.195,5631,75.04
47.28875126,48.195,4815,69.3902
47.32135058,48.195,4789,69.2026
47.3539499,48.195,4989,70.6329
47.38654922,48.195,5168,71.8888
47.41914854,48.195,5242,72.4017
47.45174786,48.195,4072,63.8122
47.48434718,48.195,3797,61.6198
47.5169465,48.195,3947,62.8252
47.54954582,48.195,4165,64.5368
47.58214514,48.195,3769,61.3922
47.61474446,48.195,3691,60.7536
47.64734378,48.195,3688,60.7289
47.6799431,48.195,3592,59.9333
47.71254242,48.195,3293,57.3847
47.74514174,48.195,3317,57.5934
47.77774106,48.195,3304,57.4804
47.81034038,48.195,3250,57.0088
47.8429397,48.195,3098,55.6597
47.87553902,48.195,3033,55.0727
47.90813834,48.195,3159,56.205
47.94073766,48.195,2976,54.5527
47.97333698,48.195,3043,55.1634
48.0059363,48.195,3007,54.8361
48.03853562,48.195,3172,56.3205
48.07113494,48.195,2900,53.8516
48.10373426,48.195,3051,55.2359
48.13633358,48.195,3001,54.7814
48.1689329,48.195,2916,54
48.20153222,48.195,2961,54.4151
48.23413154,48.195,3093,55.6147
48.26673086,48.195,2951,54.3231
48.29933018,48.195,2978,54.5711
48.3319295,48.195,3041,55.1453
48.36452882,48.195,2974,54.5344
48.39712814,48.195,3131,55.9553
48.42972746,48.195,3027,55.0182
48.46232678,48.195,2958,54.3875
48.4949261,48.195,2927,54.1018
48.52752542,48.195,2920,54.037
48.56012474,48.195,3047,55.1996
48.59272406,48.195,2983,54.6168
48.62532338,48.195,2973,54.5252
48.6579227,48.195,2983,54.6168
48.69052202,48.195,3041,55.1453
48.72312134,48.195,3126,55.9106
48.75572066,48.195,3051,55.2359
48.78831998,48.195,2947,54.2863
48.8209193,48.195,3123,55.8838
48.85351862,48.195,3043,55.1634
48.88611794,48.195,2907,53.9166
48.91871726,48.195,2992,54.6992
48.95131658,48.195,3052,55.2449
48.9839159,48.195,2888,53.7401
49.01651522,48.195,2917,54.0093
49.04911454,48.195,2856,53.4416
49.08171386,48.195,2873,53.6004
49.11431318,48.195,2903,53.8795
49.1469125,48.195,2996,54.7357
49.17951182,48.195,3084,55.5338
49.21211114,48.195,3143,56.0625
49.24471046,48.195,2991,54.69
49.27730978,48.195,2874,53.6097
49.3099091,48.195,3034,55.0818
49.34250842,48.195,2939,54.2125
49.37510774,48.195,3010,54.8635
49.40770706,48.195,2898,53.8331
49.44030638,48.195,2796,52.8772
49.4729057,48.195,2847,53.3573
49.50550502,48.195,2716,52.1153
49.53810434,48.195,2765,52.5833
49.57070366,48.195,2789,52.811
49.60330298,48.195,2879,53.6563
49.6359023,48.195,2825,53.1507
49.66850162,48.195,2860,53.479
49.70110094,48.195,2831,53.2071
49.73370026,48.195,2848,53.3667
49.76629958,48.195,2869,53.563
49.7988989,48.195,2869,53.563
49.83149822,48.195,2944,54.2586
49.86409754,48.195,2898,53.8331
49.89669686,48.195,2840,53.2917
49.92929618,48.195,2815,53.0566
49.9618955,48.195,2942,54.2402
49.99449482,48.195,3309,57.5239