File: XRD_palm_kernel_shells.csv
Measurement conditions,,,
Sample identification,m-PKS-38um-As Noturn 06-04-23,,
Comment,,,
Anode material,Cu,,
K-Alpha1 wavelength,1.540598,,
K-Alpha2 wavelength,1.544426,,
Ratio K-Alpha2/K-Alpha1,0.5,,
Divergence slit,Fixed,0.76mm,
Monochromator used,NO,,
Generator voltage,40,,
Tube current,15,,
File date and time,06/apr./2023 07:48,,
Unit cell,,,
h k l, 0 0 0,,
Scan axis,Gonio,,
Scan range,5.002,49.99992804,
Scan step size,0.0108664,,
No. of points,4141,,
Scan type,CONTINUOUS,,
Time per step,48.195,,85.92177612
[Scan points],,,
Measurements,,,
Angle, TimePerStep, Intensity, ESD
5.00743322,48.195,4933,70.2353
5.04003254,48.195,4931,70.2211
5.07263186,48.195,4930,70.214
5.10523118,48.195,4889,69.9214
5.1378305,48.195,4807,69.3325
5.17042982,48.195,5029,70.9154
5.20302914,48.195,4972,70.5124
5.23562846,48.195,4808,69.3397
5.26822778,48.195,4978,70.5549
5.3008271,48.195,4984,70.5975
5.33342642,48.195,4892,69.9428
5.36602574,48.195,4973,70.5195
5.39862506,48.195,5125,71.5891
5.43122438,48.195,4996,70.6824
5.4638237,48.195,5022,70.8661
5.49642302,48.195,5009,70.7743
5.52902234,48.195,4977,70.5479
5.56162166,48.195,5164,71.861
5.59422098,48.195,5082,71.2881
5.6268203,48.195,5064,71.1618
5.65941962,48.195,5202,72.1249
5.69201894,48.195,5234,72.3464
5.72461826,48.195,5130,71.624
5.75721758,48.195,5269,72.5879
5.7898169,48.195,5283,72.6842
5.82241622,48.195,5335,73.0411
5.85501554,48.195,5307,72.8492
5.88761486,48.195,5346,73.1163
5.92021418,48.195,5460,73.8918
5.9528135,48.195,5483,74.0473
5.98541282,48.195,5505,74.1957
6.01801214,48.195,5368,73.2666
6.05061146,48.195,5378,73.3348
6.08321078,48.195,5420,73.6206
6.1158101,48.195,5520,74.2967
6.14840942,48.195,5613,74.92
6.18100874,48.195,5647,75.1465
6.21360806,48.195,5535,74.3976
6.24620738,48.195,5549,74.4916
6.2788067,48.195,5769,75.9539
6.31140602,48.195,5646,75.1399
6.34400534,48.195,5756,75.8683
6.37660466,48.195,5767,75.9408
6.40920398,48.195,5771,75.9671
6.4418033,48.195,5720,75.6307
6.47440262,48.195,5823,76.3086
6.50700194,48.195,5928,76.9935
6.53960126,48.195,5749,75.8222
6.57220058,48.195,5955,77.1686
6.6047999,48.195,5995,77.4274
6.63739922,48.195,5961,77.2075
6.66999854,48.195,6067,77.8909
6.70259786,48.195,6055,77.8139
6.73519718,48.195,5926,76.9805
6.7677965,48.195,6039,77.711
6.80039582,48.195,6175,78.5812
6.83299514,48.195,6194,78.702
6.86559446,48.195,6157,78.4666
6.89819378,48.195,6135,78.3262
6.9307931,48.195,6135,78.3262
6.96339242,48.195,6077,77.9551
6.99599174,48.195,6257,79.1012
7.02859106,48.195,6240,78.9937
7.06119038,48.195,6334,79.5864
7.0937897,48.195,6152,78.4347
7.12638902,48.195,6214,78.8289
7.15898834,48.195,6351,79.6932
7.19158766,48.195,6474,80.4612
7.22418698,48.195,6425,80.1561
7.2567863,48.195,6543,80.8888
7.28938562,48.195,6527,80.7899
7.32198494,48.195,6394,79.9625
7.35458426,48.195,6641,81.4923
7.38718358,48.195,6678,81.719
7.4197829,48.195,6627,81.4064
7.45238222,48.195,6687,81.7741
7.48498154,48.195,6636,81.4616
7.51758086,48.195,6673,81.6884
7.55018018,48.195,6719,81.9695
7.5827795,48.195,6795,82.4318
7.61537882,48.195,6828,82.6317
7.64797814,48.195,6820,82.5833
7.68057746,48.195,6877,82.9277
7.71317678,48.195,6948,83.3547
7.7457761,48.195,7018,83.7735
7.77837542,48.195,7005,83.6959
7.81097474,48.195,6988,83.5943
7.84357406,48.195,6985,83.5763
7.87617338,48.195,6957,83.4086
7.9087727,48.195,6942,83.3187
7.94137202,48.195,7077,84.1249
7.97397134,48.195,7119,84.3742
8.00657066,48.195,7053,83.9821
8.03916998,48.195,7153,84.5754
8.0717693,48.195,7125,84.4097
8.10436862,48.195,7226,85.0059
8.13696794,48.195,7241,85.0941
8.16956726,48.195,7446,86.2902
8.20216658,48.195,7261,85.2115
8.2347659,48.195,7364,85.8138
8.26736522,48.195,7330,85.6154
8.29996454,48.195,7372,85.8604
8.33256386,48.195,7262,85.2174
8.36516318,48.195,7391,85.9709
8.3977625,48.195,7304,85.4634
8.43036182,48.195,7354,85.7555
8.46296114,48.195,7318,85.5453
8.49556046,48.195,7389,85.9593
8.52815978,48.195,7553,86.908
8.5607591,48.195,7451,86.3192
8.59335842,48.195,7596,87.155
8.62595774,48.195,7635,87.3785
8.65855706,48.195,7404,86.0465
8.69115638,48.195,7746,88.0114
8.7237557,48.195,7880,88.7694
8.75635502,48.195,7747,88.017
8.78895434,48.195,7605,87.2067
8.82155366,48.195,7795,88.2893
8.85415298,48.195,7705,87.7781
8.8867523,48.195,7727,87.9034
8.91935162,48.195,7648,87.4528
8.95195094,48.195,7842,88.5551
8.98455026,48.195,7784,88.227
9.01714958,48.195,7895,88.8538
9.0497489,48.195,7851,88.6059
9.08234822,48.195,7942,89.1179
9.11494754,48.195,7845,88.572
9.14754686,48.195,7951,89.1684
9.18014618,48.195,7841,88.5494
9.2127455,48.195,8089,89.9389
9.24534482,48.195,7981,89.3364
9.27794414,48.195,8102,90.0111
9.31054346,48.195,7976,89.3085
9.34314278,48.195,8014,89.5209
9.3757421,48.195,8061,89.7831
9.40834142,48.195,8140,90.2219
9.44094074,48.195,8071,89.8387
9.47354006,48.195,8194,90.5207
9.50613938,48.195,7969,89.2693
9.5387387,48.195,7942,89.1179
9.57133802,48.195,8013,89.5154
9.60393734,48.195,8169,90.3825
9.63653666,48.195,8103,90.0167
9.66913598,48.195,8157,90.3161
9.7017353,48.195,7971,89.2805
9.73433462,48.195,8458,91.9674
9.76693394,48.195,8215,90.6366
9.79953326,48.195,8201,90.5594
9.83213258,48.195,8263,90.901
9.8647319,48.195,8157,90.3161
9.89733122,48.195,8250,90.8295
9.92993054,48.195,8334,91.2907
9.96252986,48.195,8225,90.6918
9.99512918,48.195,8465,92.0054
10.0277285,48.195,8434,91.8368
10.06032782,48.195,8557,92.5041
10.09292714,48.195,8383,91.5587
10.12552646,48.195,8531,92.3634
10.15812578,48.195,8579,92.6229
10.1907251,48.195,8525,92.3309
10.22332442,48.195,8400,91.6515
10.25592374,48.195,8574,92.5959
10.28852306,48.195,8599,92.7308
10.32112238,48.195,8468,92.0217
10.3537217,48.195,8508,92.2388
10.38632102,48.195,8399,91.6461
10.41892034,48.195,8524,92.3255
10.45151966,48.195,8463,91.9946
10.48411898,48.195,8638,92.9408
10.5167183,48.195,8486,92.1195
10.54931762,48.195,8704,93.2952
10.58191694,48.195,8529,92.3526
10.61451626,48.195,8555,92.4932
10.64711558,48.195,8653,93.0215
10.6797149,48.195,8569,92.5689
10.71231422,48.195,8781,93.707
10.74491354,48.195,8745,93.5147
10.77751286,48.195,8716,93.3595
10.81011218,48.195,8778,93.691
10.8427115,48.195,8812,93.8723
10.87531082,48.195,8764,93.6162
10.90791014,48.195,8670,93.1128
10.94050946,48.195,8768,93.6376
10.97310878,48.195,8779,93.6963
11.0057081,48.195,8772,93.659
11.03830742,48.195,8675,93.1397
11.07090674,48.195,8719,93.3756
11.10350606,48.195,8867,94.1647
11.13610538,48.195,8799,93.803
11.1687047,48.195,8791,93.7603
11.20130402,48.195,8500,92.1954
11.23390334,48.195,8832,93.9787
11.26650266,48.195,8866,94.1594
11.29910198,48.195,8774,93.6696
11.3317013,48.195,8717,93.3649
11.36430062,48.195,8792,93.7657
11.39689994,48.195,8851,94.0798
11.42949926,48.195,8935,94.5251
11.46209858,48.195,8770,93.6483
11.4946979,48.195,8753,93.5575
11.52729722,48.195,8971,94.7154
11.55989654,48.195,8920,94.4458
11.59249586,48.195,8949,94.5992
11.62509518,48.195,8717,93.3649
11.6576945,48.195,8936,94.5304
11.69029382,48.195,9060,95.184
11.72289314,48.195,8934,94.5198
11.75549246,48.195,9156,95.687
11.78809178,48.195,8992,94.8262
11.8206911,48.195,9224,96.0417
11.85329042,48.195,8700,93.2738
11.88588974,48.195,9011,94.9263
11.91848906,48.195,9028,95.0158
11.95108838,48.195,8943,94.5674
11.9836877,48.195,9121,95.5039
12.01628702,48.195,8882,94.2444
12.04888634,48.195,9154,95.6765
12.08148566,48.195,9035,95.0526
12.11408498,48.195,9082,95.2995
12.1466843,48.195,9088,95.331
12.17928362,48.195,9018,94.9632
12.21188294,48.195,9094,95.3625
12.24448226,48.195,9028,95.0158
12.27708158,48.195,9226,96.0521
12.3096809,48.195,9128,95.5406
12.34228022,48.195,9150,95.6556
12.37487954,48.195,9382,96.8607
12.40747886,48.195,9192,95.8749
12.44007818,48.195,9283,96.3483
12.4726775,48.195,9292,96.395
12.50527682,48.195,9179,95.8071
12.53787614,48.195,9473,97.3293
12.57047546,48.195,9276,96.312
12.60307478,48.195,9245,96.1509
12.6356741,48.195,9364,96.7678
12.66827342,48.195,9568,97.8162
12.70087274,48.195,9290,96.3846
12.73347206,48.195,9323,96.5557
12.76607138,48.195,9450,97.2111
12.7986707,48.195,9483,97.3807
12.83127002,48.195,9396,96.933
12.86386934,48.195,9720,98.5901
12.89646866,48.195,9622,98.0918
12.92906798,48.195,9548,97.7139
12.9616673,48.195,9720,98.5901
12.99426662,48.195,9726,98.6205
13.02686594,48.195,9601,97.9847
13.05946526,48.195,9647,98.2191
13.09206458,48.195,9645,98.209
13.1246639,48.195,9814,99.0656
13.15726322,48.195,9936,99.6795
13.18986254,48.195,9759,98.7877
13.22246186,48.195,9934,99.6695
13.25506118,48.195,9860,99.2975
13.2876605,48.195,9868,99.3378
13.32025982,48.195,9893,99.4636
13.35285914,48.195,9927,99.6343
13.38545846,48.195,9772,98.8534
13.41805778,48.195,10053,100.2646
13.4506571,48.195,9791,98.9495
13.48325642,48.195,10092,100.4589
13.51585574,48.195,10007,100.035
13.54845506,48.195,10145,100.7224
13.58105438,48.195,10190,100.9455
13.6136537,48.195,10094,100.4689
13.64625302,48.195,10056,100.2796
13.67885234,48.195,10097,100.4838
13.71145166,48.195,10432,102.1372
13.74405098,48.195,10565,102.7862
13.7766503,48.195,10361,101.789
13.80924962,48.195,10500,102.4695
13.84184894,48.195,10403,101.9951
13.87444826,48.195,10443,102.191
13.90704758,48.195,10229,101.1385
13.9396469,48.195,10470,102.323
13.97224622,48.195,10289,101.4347
14.00484554,48.195,10530,102.6158
14.03744486,48.195,10477,102.3572
14.07004418,48.195,10861,104.2161
14.1026435,48.195,10515,102.5427
14.13524282,48.195,10708,103.4795
14.16784214,48.195,10848,104.1537
14.20044146,48.195,10698,103.4311
14.23304078,48.195,10711,103.494
14.2656401,48.195,10566,102.7911
14.29823942,48.195,10843,104.1297
14.33083874,48.195,10932,104.5562
14.36343806,48.195,10820,104.0192
14.39603738,48.195,10910,104.4509
14.4286367,48.195,10710,103.4891
14.46123602,48.195,10987,104.8189
14.49383534,48.195,10812,103.9808
14.52643466,48.195,11091,105.3138
14.55903398,48.195,11169,105.6835
14.5916333,48.195,11121,105.4562
14.62423262,48.195,10897,104.3887
14.65683194,48.195,11185,105.7592
14.68943126,48.195,11158,105.6314
14.72203058,48.195,11137,105.532
14.7546299,48.195,11192,105.7922
14.78722922,48.195,11300,106.3015
14.81982854,48.195,11274,106.1791
14.85242786,48.195,11183,105.7497
14.88502718,48.195,11493,107.2054
14.9176265,48.195,11201,105.8348
14.95022582,48.195,11221,105.9292
14.98282514,48.195,11404,106.7895
15.01542446,48.195,11304,106.3203
15.04802378,48.195,11236,106
15.0806231,48.195,11468,107.0887
15.11322242,48.195,11411,106.8223
15.14582174,48.195,11525,107.3546
15.17842106,48.195,11399,106.7661
15.21102038,48.195,11333,106.4566
15.2436197,48.195,11607,107.7358
15.27621902,48.195,11616,107.7775
15.30881834,48.195,11515,107.308
15.34141766,48.195,11385,106.7005
15.37401698,48.195,11582,107.6197
15.4066163,48.195,11576,107.5918
15.43921562,48.195,11644,107.9074
15.47181494,48.195,11533,107.3918
15.50441426,48.195,11501,107.2427
15.53701358,48.195,11612,107.759
15.5696129,48.195,11775,108.5127
15.60221222,48.195,11562,107.5267
15.63481154,48.195,11595,107.6801
15.66741086,48.195,11741,108.3559
15.70001018,48.195,11771,108.4942
15.7326095,48.195,11773,108.5035
15.76520882,48.195,11691,108.1249
15.79780814,48.195,11614,107.7683
15.83040746,48.195,11710,108.2128
15.86300678,48.195,11731,108.3097
15.8956061,48.195,11819,108.7152
15.92820542,48.195,11967,109.3938
15.96080474,48.195,11828,108.7566
15.99340406,48.195,11659,107.9768
16.02600338,48.195,11608,107.7404
16.0586027,48.195,11733,108.319
16.09120202,48.195,11793,108.5956
16.12380134,48.195,11761,108.4481
16.15640066,48.195,11865,108.9266
16.18899998,48.195,11621,107.8007
16.2215993,48.195,11788,108.5726
16.25419862,48.195,11803,108.6416
16.28679794,48.195,11660,107.9815
16.31939726,48.195,11680,108.074
16.35199658,48.195,11713,108.2266
16.3845959,48.195,11973,109.4212
16.41719522,48.195,11737,108.3374
16.44979454,48.195,11678,108.0648
16.48239386,48.195,11478,107.1354
16.51499318,48.195,11667,108.0139
16.5475925,48.195,11669,108.0231
16.58019182,48.195,11697,108.1527
16.61279114,48.195,11436,106.9392
16.64539046,48.195,11692,108.1296
16.67798978,48.195,11907,109.1192
16.7105891,48.195,11510,107.2847
16.74318842,48.195,11770,108.4896
16.77578774,48.195,11526,107.3592
16.80838706,48.195,11959,109.3572
16.84098638,48.195,11794,108.6002
16.8735857,48.195,11906,109.1146
16.90618502,48.195,11603,107.7172
16.93878434,48.195,11719,108.2543
16.97138366,48.195,11744,108.3697
17.00398298,48.195,11615,107.7729
17.0365823,48.195,11823,108.7336
17.06918162,48.195,11841,108.8164
17.10178094,48.195,11652,107.9444
17.13438026,48.195,11813,108.6876
17.16697958,48.195,11711,108.2174
17.1995789,48.195,11835,108.7888
17.23217822,48.195,11757,108.4297
17.26477754,48.195,11668,108.0185
17.29737686,48.195,11779,108.5311
17.32997618,48.195,11645,107.912
17.3625755,48.195,11596,107.6847
17.39517482,48.195,11475,107.1214
17.42777414,48.195,11517,107.3173
17.46037346,48.195,11723,108.2728
17.49297278,48.195,11513,107.2986
17.5255721,48.195,11468,107.0887
17.55817142,48.195,11536,107.4058
17.59077074,48.195,11701,108.1712
17.62337006,48.195,11567,107.55
17.65596938,48.195,11401,106.7755
17.6885687,48.195,11552,107.4802
17.72116802,48.195,11403,106.7848
17.75376734,48.195,11682,108.0833
17.78636666,48.195,11501,107.2427
17.81896598,48.195,11600,107.7033
17.8515653,48.195,11613,107.7636
17.88416462,48.195,11744,108.3697
17.91676394,48.195,11613,107.7636
17.94936326,48.195,11514,107.3033
17.98196258,48.195,11818,108.7106
18.0145619,48.195,11570,107.5639
18.04716122,48.195,11567,107.55
18.07976054,48.195,11550,107.4709
18.11235986,48.195,11629,107.8378
18.14495918,48.195,11596,107.6847
18.1775585,48.195,11755,108.4205
18.21015782,48.195,11713,108.2266
18.24275714,48.195,11626,107.8239
18.27535646,48.195,11686,108.1018
18.30795578,48.195,11630,107.8425
18.3405551,48.195,11589,107.6522
18.37315442,48.195,11728,108.2959
18.40575374,48.195,11665,108.0046
18.43835306,48.195,11774,108.5081
18.47095238,48.195,11756,108.4251
18.5035517,48.195,11828,108.7566
18.53615102,48.195,11709,108.2081
18.56875034,48.195,11722,108.2682
18.60134966,48.195,11809,108.6692
18.63394898,48.195,11812,108.683
18.6665483,48.195,11930,109.2245
18.69914762,48.195,11885,109.0183
18.73174694,48.195,11970,109.4075
18.76434626,48.195,12038,109.7178
18.79694558,48.195,11946,109.2978
18.8295449,48.195,12041,109.7315
18.86214422,48.195,11958,109.3526
18.89474354,48.195,11965,109.3846
18.92734286,48.195,11860,108.9036
18.95994218,48.195,12116,110.0727
18.9925415,48.195,12087,109.9409
19.02514082,48.195,12235,110.6119
19.05774014,48.195,12174,110.3359
19.09033946,48.195,12106,110.0273
19.12293878,48.195,12289,110.8558
19.1555381,48.195,12284,110.8332
19.18813742,48.195,12318,110.9865
19.22073674,48.195,12205,110.4762
19.25333606,48.195,12487,111.7452
19.28593538,48.195,12285,110.8377
19.3185347,48.195,12573,112.1294
19.35113402,48.195,12507,111.8347
19.38373334,48.195,12376,111.2475
19.41633266,48.195,12773,113.0177
19.44893198,48.195,12717,112.7697
19.4815313,48.195,12637,112.4144
19.51413062,48.195,12681,112.6099
19.54672994,48.195,12884,113.5077
19.57932926,48.195,12975,113.9079
19.61192858,48.195,12983,113.943
19.6445279,48.195,12986,113.9561
19.67712722,48.195,13083,114.3809
19.70972654,48.195,13239,115.0609
19.74232586,48.195,13295,115.3039
19.77492518,48.195,13196,114.8738
19.8075245,48.195,13464,116.0345
19.84012382,48.195,13297,115.3126
19.87272314,48.195,13645,116.8118
19.90532246,48.195,13423,115.8577
19.93792178,48.195,13461,116.0215
19.9705211,48.195,13577,116.5204
20.00312042,48.195,13888,117.8474
20.03571974,48.195,14103,118.7561
20.06831906,48.195,13794,117.4479
20.10091838,48.195,14117,118.815
20.1335177,48.195,13816,117.5415
20.16611702,48.195,13886,117.8389
20.19871634,48.195,14225,119.2686
20.23131566,48.195,14179,119.0756
20.26391498,48.195,14128,118.8613
20.2965143,48.195,14424,120.1
20.32911362,48.195,14427,120.1124
20.36171294,48.195,14489,120.3703
20.39431226,48.195,14473,120.3038
20.42691158,48.195,14769,121.5278
20.4595109,48.195,14678,121.1528
20.49211022,48.195,14850,121.8606
20.52470954,48.195,14818,121.7292
20.55730886,48.195,14687,121.1899
20.58990818,48.195,14707,121.2724
20.6225075,48.195,14970,122.352
20.65510682,48.195,15118,122.9553
20.68770614,48.195,15120,122.9634
20.72030546,48.195,15494,124.4749
20.75290478,48.195,15255,123.5111
20.7855041,48.195,15354,123.9113
20.81810342,48.195,15490,124.4588
20.85070274,48.195,15684,125.2358
20.88330206,48.195,15667,125.1679
20.91590138,48.195,15684,125.2358
20.9485007,48.195,15798,125.6901
20.98110002,48.195,15998,126.4832
21.01369934,48.195,15948,126.2854
21.04629866,48.195,16006,126.5148
21.07889798,48.195,15774,125.5946
21.1114973,48.195,16064,126.7438
21.14409662,48.195,16499,128.4484
21.17669594,48.195,16285,127.6127
21.20929526,48.195,16192,127.2478
21.24189458,48.195,16290,127.6323
21.2744939,48.195,16284,127.6088
21.30709322,48.195,16492,128.4212
21.33969254,48.195,16650,129.0349
21.37229186,48.195,16600,128.841
21.40489118,48.195,16303,127.6832
21.4374905,48.195,16394,128.0391
21.47008982,48.195,16742,129.3909
21.50268914,48.195,16588,128.7944
21.53528846,48.195,16750,129.4218
21.56788778,48.195,16917,130.0654
21.6004871,48.195,16894,129.9769
21.63308642,48.195,17077,130.679
21.66568574,48.195,16613,128.8914
21.69828506,48.195,16874,129.9
21.73088438,48.195,16906,130.0231
21.7634837,48.195,17117,130.832
21.79608302,48.195,16961,130.2344
21.82868234,48.195,16998,130.3764
21.86128166,48.195,16982,130.315
21.89388098,48.195,16928,130.1076
21.9264803,48.195,16875,129.9038
21.95907962,48.195,16875,129.9038
21.99167894,48.195,16785,129.5569
22.02427826,48.195,16928,130.1076
22.05687758,48.195,16845,129.7883
22.0894769,48.195,16689,129.1859
22.12207622,48.195,16496,128.4368
22.15467554,48.195,16774,129.5145
22.18727486,48.195,16221,127.3617
22.21987418,48.195,16443,128.2303
22.2524735,48.195,16591,128.8061
22.28507282,48.195,16305,127.691
22.31767214,48.195,16448,128.2498
22.35027146,48.195,16451,128.2615
22.38287078,48.195,16044,126.6649
22.4154701,48.195,16019,126.5662
22.44806942,48.195,16095,126.8661
22.48066874,48.195,15926,126.1983
22.51326806,48.195,15933,126.226
22.54586738,48.195,15863,125.9484
22.5784667,48.195,15694,125.2757
22.61106602,48.195,15968,126.3646
22.64366534,48.195,15595,124.8799
22.67626466,48.195,15482,124.4267
22.70886398,48.195,15406,124.1209
22.7414633,48.195,15081,122.8047
22.77406262,48.195,15039,122.6336
22.80666194,48.195,14985,122.4132
22.83926126,48.195,14949,122.2661
22.87186058,48.195,15004,122.4908
22.9044599,48.195,14724,121.3425
22.93705922,48.195,14605,120.8511
22.96965854,48.195,14531,120.5446
23.00225786,48.195,14436,120.1499
23.03485718,48.195,13927,118.0127
23.0674565,48.195,14318,119.6578
23.10005582,48.195,14033,118.461
23.13265514,48.195,13834,117.618
23.16525446,48.195,13676,116.9444
23.19785378,48.195,13264,115.1694
23.2304531,48.195,13479,116.0991
23.26305242,48.195,13477,116.0905
23.29565174,48.195,13352,115.5509
23.32825106,48.195,13346,115.5249
23.36085038,48.195,12989,113.9693
23.3934497,48.195,12811,113.1857
23.42604902,48.195,12868,113.4372
23.45864834,48.195,12971,113.8903
23.49124766,48.195,12771,113.0088
23.52384698,48.195,12786,113.0752
23.5564463,48.195,12569,112.1116
23.58904562,48.195,12549,112.0223
23.62164494,48.195,12390,111.3104
23.65424426,48.195,12061,109.8226
23.68684358,48.195,12087,109.9409
23.7194429,48.195,11885,109.0183
23.75204222,48.195,12000,109.5445
23.78464154,48.195,11840,108.8118
23.81724086,48.195,11863,108.9174
23.84984018,48.195,11600,107.7033
23.8824395,48.195,11566,107.5453
23.91503882,48.195,11315,106.372
23.94763814,48.195,11155,105.6172
23.98023746,48.195,11216,105.9056
24.01283678,48.195,11300,106.3015
24.0454361,48.195,11248,106.0566
24.07803542,48.195,11214,105.8962
24.11063474,48.195,11168,105.6788
24.14323406,48.195,10924,104.5179
24.17583338,48.195,10893,104.3695
24.2084327,48.195,11052,105.1285
24.24103202,48.195,10641,103.1552
24.27363134,48.195,10720,103.5374
24.30623066,48.195,10566,102.7911
24.33882998,48.195,10605,102.9806
24.3714293,48.195,10447,102.2106
24.40402862,48.195,10217,101.0792
24.43662794,48.195,10493,102.4353
24.46922726,48.195,10111,100.5535
24.50182658,48.195,10369,101.8283
24.5344259,48.195,10082,100.4092
24.56702522,48.195,10242,101.2028
24.59962454,48.195,10161,100.8018
24.63222386,48.195,10089,100.444
24.66482318,48.195,9931,99.6544
24.6974225,48.195,9855,99.2724
24.73002182,48.195,10044,100.2198
24.76262114,48.195,10094,100.4689
24.79522046,48.195,9688,98.4276
24.82781978,48.195,9832,99.1564
24.8604191,48.195,9766,98.8231
24.89301842,48.195,9583,97.8928
24.92561774,48.195,9594,97.949
24.95821706,48.195,9487,97.4012
24.99081638,48.195,9468,97.3036
25.0234157,48.195,9592,97.9388
25.05601502,48.195,9664,98.3056
25.08861434,48.195,9479,97.3602
25.12121366,48.195,9260,96.2289
25.15381298,48.195,9407,96.9897
25.1864123,48.195,9273,96.2964
25.21901162,48.195,9166,95.7392
25.25161094,48.195,9145,95.6295
25.28421026,48.195,9213,95.9844
25.31680958,48.195,8989,94.8103
25.3494089,48.195,9144,95.6243
25.38200822,48.195,8953,94.6203
25.41460754,48.195,9193,95.8801
25.44720686,48.195,8960,94.6573
25.47980618,48.195,8878,94.2231
25.5124055,48.195,8991,94.8209
25.54500482,48.195,8854,94.0957
25.57760414,48.195,8988,94.8051
25.61020346,48.195,8847,94.0585
25.64280278,48.195,8930,94.4987
25.6754021,48.195,8669,93.1075
25.70800142,48.195,8823,93.9308
25.74060074,48.195,8909,94.3875
25.77320006,48.195,8640,92.9516
25.80579938,48.195,8637,92.9355
25.8383987,48.195,8710,93.3274
25.87099802,48.195,8749,93.5361
25.90359734,48.195,8746,93.5201
25.93619666,48.195,8694,93.2416
25.96879598,48.195,8634,92.9193
26.0013953,48.195,8579,92.6229
26.03399462,48.195,8606,92.7685
26.06659394,48.195,8503,92.2117
26.09919326,48.195,8281,91
26.13179258,48.195,8385,91.5696
26.1643919,48.195,8401,91.657
26.19699122,48.195,8360,91.433
26.22959054,48.195,8553,92.4824
26.26218986,48.195,8470,92.0326
26.29478918,48.195,8377,91.526
26.3273885,48.195,8345,91.351
26.35998782,48.195,8360,91.433
26.39258714,48.195,8423,91.7769
26.42518646,48.195,8290,91.0494
26.45778578,48.195,8250,90.8295
26.4903851,48.195,8337,91.3072
26.52298442,48.195,8084,89.9111
26.55558374,48.195,8366,91.4658
26.58818306,48.195,8311,91.1647
26.62078238,48.195,8062,89.7886
26.6533817,48.195,8085,89.9166
26.68598102,48.195,7965,89.2468
26.71858034,48.195,8035,89.6382
26.75117966,48.195,7785,88.2326
26.78377898,48.195,7941,89.1123
26.8163783,48.195,8092,89.9555
26.84897762,48.195,7969,89.2693
26.88157694,48.195,7993,89.4036
26.91417626,48.195,7843,88.5607
26.94677558,48.195,8026,89.5879
26.9793749,48.195,8045,89.6939
27.01197422,48.195,7837,88.5268
27.04457354,48.195,7937,89.0898
27.07717286,48.195,7951,89.1684
27.10977218,48.195,7785,88.2326
27.1423715,48.195,7786,88.2383
27.17497082,48.195,7660,87.5214
27.20757014,48.195,7677,87.6185
27.24016946,48.195,7737,87.9602
27.27276878,48.195,7755,88.0625
27.3053681,48.195,7915,88.9663
27.33796742,48.195,7731,87.9261
27.37056674,48.195,7605,87.2067
27.40316606,48.195,7751,88.0398
27.43576538,48.195,7665,87.55
27.4683647,48.195,7545,86.862
27.50096402,48.195,7703,87.7667
27.53356334,48.195,7685,87.6641
27.56616266,48.195,7620,87.2926
27.59876198,48.195,7655,87.4929
27.6313613,48.195,7520,86.7179
27.66396062,48.195,7721,87.8692
27.69655994,48.195,7624,87.3155
27.72915926,48.195,7578,87.0517
27.76175858,48.195,7640,87.4071
27.7943579,48.195,7632,87.3613
27.82695722,48.195,7465,86.4002
27.85955654,48.195,7410,86.0814
27.89215586,48.195,7343,85.6913
27.92475518,48.195,7428,86.1858
27.9573545,48.195,7386,85.9418
27.98995382,48.195,7458,86.3597
28.02255314,48.195,7274,85.2877
28.05515246,48.195,7377,85.8895
28.08775178,48.195,7288,85.3698
28.1203511,48.195,7276,85.2995
28.15295042,48.195,7144,84.5222
28.18554974,48.195,7293,85.3991
28.21814906,48.195,7166,84.6522
28.25074838,48.195,7129,84.4334
28.2833477,48.195,7231,85.0353
28.31594702,48.195,7051,83.9702
28.34854634,48.195,7132,84.4512
28.38114566,48.195,7228,85.0176
28.41374498,48.195,7139,84.4926
28.4463443,48.195,7176,84.7113
28.47894362,48.195,7064,84.0476
28.51154294,48.195,7144,84.5222
28.54414226,48.195,7200,84.8528
28.57674158,48.195,6982,83.5584
28.6093409,48.195,6926,83.2226
28.64194022,48.195,6962,83.4386
28.67453954,48.195,7076,84.119
28.70713886,48.195,6858,82.813
28.73973818,48.195,7020,83.7854
28.7723375,48.195,6950,83.3667
28.80493682,48.195,6999,83.66
28.83753614,48.195,7053,83.9821
28.87013546,48.195,6903,83.0843
28.90273478,48.195,6956,83.4026
28.9353341,48.195,6969,83.4805
28.96793342,48.195,7035,83.8749
29.00053274,48.195,7053,83.9821
29.03313206,48.195,6944,83.3307
29.06573138,48.195,6964,83.4506
29.0983307,48.195,6894,83.0301
29.13093002,48.195,6888,82.994
29.16352934,48.195,6851,82.7708
29.19612866,48.195,6726,82.0122
29.22872798,48.195,6626,81.4002
29.2613273,48.195,6833,82.662
29.29392662,48.195,6714,81.939
29.32652594,48.195,6837,82.6862
29.35912526,48.195,6715,81.9451
29.39172458,48.195,6655,81.5782
29.4243239,48.195,6719,81.9695
29.45692322,48.195,6924,83.2106
29.48952254,48.195,6772,82.2922
29.52212186,48.195,6889,83
29.55472118,48.195,6636,81.4616
29.5873205,48.195,6787,82.3833
29.61991982,48.195,6497,80.604
29.65251914,48.195,6669,81.6639
29.68511846,48.195,6762,82.2314
29.71771778,48.195,6496,80.5978
29.7503171,48.195,6754,82.1827
29.78291642,48.195,6543,80.8888
29.81551574,48.195,6619,81.3572
29.84811506,48.195,6707,81.8963
29.88071438,48.195,6601,81.2465
29.9133137,48.195,6578,81.1049
29.94591302,48.195,6494,80.5854
29.97851234,48.195,6454,80.3368
30.01111166,48.195,6486,80.5357
30.04371098,48.195,6463,80.3928
30.0763103,48.195,6473,80.455
30.10890962,48.195,6426,80.1623
30.14150894,48.195,6437,80.2309
30.17410826,48.195,6383,79.8937
30.20670758,48.195,6391,79.9437
30.2393069,48.195,6336,79.599
30.27190622,48.195,6415,80.0937
30.30450554,48.195,6447,80.2932
30.33710486,48.195,6348,79.6743
30.36970418,48.195,6374,79.8373
30.4023035,48.195,6489,80.5543
30.43490282,48.195,6165,78.5175
30.46750214,48.195,6274,79.2086
30.50010146,48.195,6394,79.9625
30.53270078,48.195,6285,79.278
30.5653001,48.195,6314,79.4607
30.59789942,48.195,6414,80.0875
30.63049874,48.195,6188,78.6638
30.66309806,48.195,6236,78.9683
30.69569738,48.195,6208,78.7909
30.7282967,48.195,6137,78.339
30.76089602,48.195,6200,78.7401
30.79349534,48.195,6207,78.7845
30.82609466,48.195,6159,78.4793
30.85869398,48.195,6017,77.5693
30.8912933,48.195,6201,78.7464
30.92389262,48.195,6163,78.5048
30.95649194,48.195,6333,79.5801
30.98909126,48.195,5997,77.4403
31.02169058,48.195,6198,78.7274
31.0542899,48.195,6143,78.3773
31.08688922,48.195,6161,78.492
31.11948854,48.195,6126,78.2688
31.15208786,48.195,6122,78.2432
31.18468718,48.195,6020,77.5887
31.2172865,48.195,6092,78.0513
31.24988582,48.195,6113,78.1857
31.28248514,48.195,5894,76.7724
31.31508446,48.195,6094,78.0641
31.34768378,48.195,5861,76.5572
31.3802831,48.195,6055,77.8139
31.41288242,48.195,6001,77.4661
31.44548174,48.195,6093,78.0577
31.47808106,48.195,5985,77.3628
31.51068038,48.195,6068,77.8974
31.5432797,48.195,6061,77.8524
31.57587902,48.195,5899,76.8049
31.60847834,48.195,6024,77.6144
31.64107766,48.195,5891,76.7529
31.67367698,48.195,5947,77.1168
31.7062763,48.195,5727,75.6769
31.73887562,48.195,6010,77.5242
31.77147494,48.195,5910,76.8765
31.80407426,48.195,5912,76.8895
31.83667358,48.195,5826,76.3282
31.8692729,48.195,5978,77.3175
31.90187222,48.195,5976,77.3046
31.93447154,48.195,6048,77.7689
31.96707086,48.195,6025,77.6209
31.99967018,48.195,5901,76.818
32.0322695,48.195,5896,76.7854
32.06486882,48.195,5802,76.1709
32.09746814,48.195,5935,77.039
32.13006746,48.195,5820,76.2889
32.16266678,48.195,5914,76.9025
32.1952661,48.195,5730,75.6968
32.22786542,48.195,5848,76.4722
32.26046474,48.195,5829,76.3479
32.29306406,48.195,5880,76.6812
32.32566338,48.195,5909,76.87
32.3582627,48.195,5784,76.0526
32.39086202,48.195,5943,77.0909
32.42346134,48.195,5833,76.3741
32.45606066,48.195,5833,76.3741
32.48865998,48.195,5742,75.776
32.5212593,48.195,5953,77.1557
32.55385862,48.195,5798,76.1446
32.58645794,48.195,5777,76.0066
32.61905726,48.195,5932,77.0195
32.65165658,48.195,5919,76.935
32.6842559,48.195,5770,75.9605
32.71685522,48.195,5949,77.1298
32.74945454,48.195,5770,75.9605
32.78205386,48.195,5756,75.8683
32.81465318,48.195,5863,76.5702
32.8472525,48.195,5720,75.6307
32.87985182,48.195,5721,75.6373
32.91245114,48.195,5838,76.4068
32.94505046,48.195,5787,76.0723
32.97764978,48.195,6003,77.479
33.0102491,48.195,5768,75.9474
33.04284842,48.195,5830,76.3544
33.07544774,48.195,5862,76.5637
33.10804706,48.195,5871,76.6225
33.14064638,48.195,5887,76.7268
33.1732457,48.195,5888,76.7333
33.20584502,48.195,5863,76.5702
33.23844434,48.195,5797,76.138
33.27104366,48.195,5952,77.1492
33.30364298,48.195,6068,77.8974
33.3362423,48.195,5894,76.7724
33.36884162,48.195,5782,76.0395
33.40144094,48.195,5917,76.922
33.43404026,48.195,5786,76.0658
33.46663958,48.195,5943,77.0909
33.4992389,48.195,6043,77.7367
33.53183822,48.195,6070,77.9102
33.56443754,48.195,6120,78.2304
33.59703686,48.195,5994,77.4209
33.62963618,48.195,5948,77.1233
33.6622355,48.195,6064,77.8717
33.69483482,48.195,5874,76.642
33.72743414,48.195,5992,77.408
33.76003346,48.195,5914,76.9025
33.79263278,48.195,6050,77.7817
33.8252321,48.195,5974,77.2917
33.85783142,48.195,5865,76.5833
33.89043074,48.195,6142,78.3709
33.92303006,48.195,6038,77.7046
33.95562938,48.195,6077,77.9551
33.9882287,48.195,5997,77.4403
34.02082802,48.195,6158,78.4729
34.05342734,48.195,6044,77.7432
34.08602666,48.195,6052,77.7946
34.11862598,48.195,6189,78.6702
34.1512253,48.195,6075,77.9423
34.18382462,48.195,6212,78.8162
34.21642394,48.195,6151,78.4283
34.24902326,48.195,6239,78.9873
34.28162258,48.195,6173,78.5684
34.3142219,48.195,6237,78.9747
34.34682122,48.195,6342,79.6367
34.37942054,48.195,6339,79.6178
34.41201986,48.195,6362,79.7621
34.44461918,48.195,6158,78.4729
34.4772185,48.195,6561,81
34.50981782,48.195,6440,80.2496
34.54241714,48.195,6474,80.4612
34.57501646,48.195,6418,80.1124
34.60761578,48.195,6486,80.5357
34.6402151,48.195,6394,79.9625
34.67281442,48.195,6386,79.9125
34.70541374,48.195,6350,79.6869
34.73801306,48.195,6308,79.4229
34.77061238,48.195,6229,78.924
34.8032117,48.195,6149,78.4156
34.83581102,48.195,6166,78.5239
34.86841034,48.195,5996,77.4338
34.90100966,48.195,6167,78.5302
34.93360898,48.195,6041,77.7239
34.9662083,48.195,6081,77.9808
34.99880762,48.195,5934,77.0325
35.03140694,48.195,5904,76.8375
35.06400626,48.195,6062,77.8588
35.09660558,48.195,5724,75.6571
35.1292049,48.195,6011,77.5306
35.16180422,48.195,5979,77.324
35.19440354,48.195,5931,77.013
35.22700286,48.195,5916,76.9155
35.25960218,48.195,5883,76.7007
35.2922015,48.195,5884,76.7072
35.32480082,48.195,5876,76.6551
35.35740014,48.195,5842,76.433
35.38999946,48.195,5791,76.0986
35.42259878,48.195,5930,77.0065
35.4551981,48.195,5725,75.6637
35.48779742,48.195,5576,74.6726
35.52039674,48.195,5846,76.4591
35.55299606,48.195,5747,75.809
35.58559538,48.195,5885,76.7138
35.6181947,48.195,5664,75.2596
35.65079402,48.195,5640,75.0999
35.68339334,48.195,5759,75.8881
35.71599266,48.195,5756,75.8683
35.74859198,48.195,5602,74.8465
35.7811913,48.195,5831,76.361
35.81379062,48.195,5744,75.7892
35.84638994,48.195,5758,75.8815
35.87898926,48.195,5532,74.3774
35.91158858,48.195,5702,75.5116
35.9441879,48.195,5660,75.233
35.97678722,48.195,5526,74.3371
36.00938654,48.195,5693,75.452
36.04198586,48.195,5716,75.6042
36.07458518,48.195,5706,75.5381
36.1071845,48.195,5691,75.4387
36.13978382,48.195,5634,75.06
36.17238314,48.195,5556,74.5386
36.20498246,48.195,5538,74.4177
36.23758178,48.195,5609,74.8933
36.2701811,48.195,5556,74.5386
36.30278042,48.195,5570,74.6324
36.33537974,48.195,5509,74.2226
36.36797906,48.195,5543,74.4513
36.40057838,48.195,5483,74.0473
36.4331777,48.195,5591,74.773
36.46577702,48.195,5530,74.364
36.49837634,48.195,5506,74.2024
36.53097566,48.195,5449,73.8173
36.56357498,48.195,5527,74.3438
36.5961743,48.195,5411,73.5595
36.62877362,48.195,5502,74.1755
36.66137294,48.195,5382,73.3621
36.69397226,48.195,5344,73.1027
36.72657158,48.195,5468,73.9459
36.7591709,48.195,5405,73.5187
36.79177022,48.195,5371,73.2871
36.82436954,48.195,5353,73.1642
36.85696886,48.195,5399,73.4779
36.88956818,48.195,5547,74.4782
36.9221675,48.195,5421,73.6274
36.95476682,48.195,5295,72.7668
36.98736614,48.195,5483,74.0473
37.01996546,48.195,5458,73.8783
37.05256478,48.195,5370,73.2803
37.0851641,48.195,5415,73.5867
37.11776342,48.195,5359,73.2052
37.15036274,48.195,5386,73.3894
37.18296206,48.195,5332,73.0205
37.21556138,48.195,5184,72
37.2481607,48.195,5417,73.6003
37.28076002,48.195,5337,73.0548
37.31335934,48.195,5313,72.8903
37.34595866,48.195,5172,71.9166
37.37855798,48.195,5491,74.1013
37.4111573,48.195,5329,73
37.44375662,48.195,5548,74.4849
37.47635594,48.195,5352,73.1574
37.50895526,48.195,5274,72.6223
37.54155458,48.195,5314,72.8972
37.5741539,48.195,5371,73.2871
37.60675322,48.195,5393,73.437
37.63935254,48.195,5411,73.5595
37.67195186,48.195,5211,72.1873
37.70455118,48.195,5222,72.2634
37.7371505,48.195,5239,72.3809
37.76974982,48.195,5341,73.0821
37.80234914,48.195,5244,72.4155
37.83494846,48.195,5329,73
37.86754778,48.195,5356,73.1847
37.9001471,48.195,5408,73.5391
37.93274642,48.195,5354,73.171
37.96534574,48.195,5148,71.7496
37.99794506,48.195,5294,72.7599
38.03054438,48.195,5416,73.5935
38.0631437,48.195,5392,73.4302
38.09574302,48.195,5270,72.5948
38.12834234,48.195,5359,73.2052
38.16094166,48.195,5493,74.1148
38.19354098,48.195,5460,73.8918
38.2261403,48.195,5510,74.2294
38.25873962,48.195,5451,73.8309
38.29133894,48.195,5290,72.7324
38.32393826,48.195,5264,72.5534
38.35653758,48.195,5391,73.4234
38.3891369,48.195,5261,72.5328
38.42173622,48.195,5274,72.6223
38.45433554,48.195,5397,73.4643
38.48693486,48.195,5449,73.8173
38.51953418,48.195,5369,73.2735
38.5521335,48.195,5394,73.4439
38.58473282,48.195,5312,72.8835
38.61733214,48.195,5330,73.0068
38.64993146,48.195,5140,71.6938
38.68253078,48.195,5120,71.5542
38.7151301,48.195,5185,72.0069
38.74772942,48.195,5269,72.5879
38.78032874,48.195,5123,71.5751
38.81292806,48.195,5134,71.6519
38.84552738,48.195,5166,71.8749
38.8781267,48.195,5121,71.5612
38.91072602,48.195,5025,70.8872
38.94332534,48.195,5115,71.5192
38.97592466,48.195,5104,71.4423
39.00852398,48.195,5218,72.2357
39.0411233,48.195,5179,71.9653
39.07372262,48.195,5183,71.9931
39.10632194,48.195,5198,72.0972
39.13892126,48.195,5110,71.4843
39.17152058,48.195,5105,71.4493
39.2041199,48.195,5049,71.0563
39.23671922,48.195,5084,71.3022
39.26931854,48.195,5009,70.7743
39.30191786,48.195,5186,72.0139
39.33451718,48.195,5036,70.9648
39.3671165,48.195,5051,71.0704
39.39971582,48.195,5166,71.8749
39.43231514,48.195,5097,71.3933
39.46491446,48.195,5204,72.1388
39.49751378,48.195,4959,70.4202
39.5301131,48.195,5154,71.7914
39.56271242,48.195,5250,72.4569
39.59531174,48.195,5197,72.0902
39.62791106,48.195,5025,70.8872
39.66051038,48.195,5044,71.0211
39.6931097,48.195,5080,71.2741
39.72570902,48.195,5111,71.4913
39.75830834,48.195,5168,71.8888
39.79090766,48.195,5138,71.6798
39.82350698,48.195,5107,71.4633
39.8561063,48.195,5222,72.2634
39.88870562,48.195,5072,71.218
39.92130494,48.195,5213,72.2011
39.95390426,48.195,5008,70.7672
39.98650358,48.195,4977,70.5479
40.0191029,48.195,5093,71.3653
40.05170222,48.195,5061,71.1407
40.08430154,48.195,5178,71.9583
40.11690086,48.195,5125,71.5891
40.14950018,48.195,4957,70.406
40.1820995,48.195,5176,71.9444
40.21469882,48.195,5033,70.9436
40.24729814,48.195,5088,71.3302
40.27989746,48.195,5043,71.0141
40.31249678,48.195,5070,71.2039
40.3450961,48.195,5114,71.5122
40.37769542,48.195,5139,71.6868
40.41029474,48.195,5130,71.624
40.44289406,48.195,4897,69.9786
40.47549338,48.195,5064,71.1618
40.5080927,48.195,5135,71.6589
40.54069202,48.195,5155,71.7983
40.57329134,48.195,5084,71.3022
40.60589066,48.195,4952,70.3704
40.63848998,48.195,5128,71.6101
40.6710893,48.195,5090,71.3442
40.70368862,48.195,5060,71.1337
40.73628794,48.195,5278,72.6498
40.76888726,48.195,5117,71.5332
40.80148658,48.195,5077,71.2531
40.8340859,48.195,5070,71.2039
40.86668522,48.195,5077,71.2531
40.89928454,48.195,5054,71.0915
40.93188386,48.195,5026,70.8943
40.96448318,48.195,5169,71.8958
40.9970825,48.195,5063,71.1548
41.02968182,48.195,5124,71.5821
41.06228114,48.195,5103,71.4353
41.09488046,48.195,5154,71.7914
41.12747978,48.195,4993,70.6612
41.1600791,48.195,5014,70.8096
41.19267842,48.195,4942,70.2994
41.22527774,48.195,4961,70.4344
41.25787706,48.195,4934,70.2424
41.29047638,48.195,5047,71.0422
41.3230757,48.195,5043,71.0141
41.35567502,48.195,5003,70.7319
41.38827434,48.195,4965,70.4628
41.42087366,48.195,5083,71.2952
41.45347298,48.195,5113,71.5052
41.4860723,48.195,5140,71.6938
41.51867162,48.195,4977,70.5479
41.55127094,48.195,4976,70.5408
41.58387026,48.195,5070,71.2039
41.61646958,48.195,5078,71.2601
41.6490689,48.195,4942,70.2994
41.68166822,48.195,4933,70.2353
41.71426754,48.195,4811,69.3614
41.74686686,48.195,4894,69.9571
41.77946618,48.195,4935,70.2496
41.8120655,48.195,4946,70.3278
41.84466482,48.195,4973,70.5195
41.87726414,48.195,4995,70.6753
41.90986346,48.195,4908,70.0571
41.94246278,48.195,4923,70.1641
41.9750621,48.195,4900,70
42.00766142,48.195,5050,71.0634
42.04026074,48.195,4887,69.9071
42.07286006,48.195,4974,70.5266
42.10545938,48.195,4812,69.3686
42.1380587,48.195,5017,70.8308
42.17065802,48.195,4910,70.0714
42.20325734,48.195,4931,70.2211
42.23585666,48.195,4748,68.9057
42.26845598,48.195,4916,70.1142
42.3010553,48.195,4841,69.5773
42.33365462,48.195,4954,70.3847
42.36625394,48.195,4892,69.9428
42.39885326,48.195,4995,70.6753
42.43145258,48.195,4938,70.2709
42.4640519,48.195,4868,69.7711
42.49665122,48.195,4921,70.1498
42.52925054,48.195,4947,70.3349
42.56184986,48.195,4818,69.4118
42.59444918,48.195,5049,71.0563
42.6270485,48.195,4904,70.0286
42.65964782,48.195,4993,70.6612
42.69224714,48.195,4896,69.9714
42.72484646,48.195,4794,69.2387
42.75744578,48.195,4974,70.5266
42.7900451,48.195,4899,69.9929
42.82264442,48.195,4801,69.2892
42.85524374,48.195,4810,69.3542
42.88784306,48.195,4881,69.8642
42.92044238,48.195,4979,70.562
42.9530417,48.195,4770,69.0652
42.98564102,48.195,4848,69.6276
43.01824034,48.195,4819,69.419
43.05083966,48.195,4887,69.9071
43.08343898,48.195,4831,69.5054
43.1160383,48.195,4712,68.644
43.14863762,48.195,4854,69.6707
43.18123694,48.195,4789,69.2026
43.21383626,48.195,4805,69.3181
43.24643558,48.195,4735,68.8113
43.2790349,48.195,4717,68.6804
43.31163422,48.195,4844,69.5989
43.34423354,48.195,4806,69.3253
43.37683286,48.195,4808,69.3397
43.40943218,48.195,4616,67.9412
43.4420315,48.195,4789,69.2026
43.47463082,48.195,4713,68.6513
43.50723014,48.195,4769,69.0579
43.53982946,48.195,4898,69.9857
43.57242878,48.195,4728,68.7605
43.6050281,48.195,4766,69.0362
43.63762742,48.195,4742,68.8622
43.67022674,48.195,4831,69.5054
43.70282606,48.195,4836,69.5414
43.73542538,48.195,4663,68.2862
43.7680247,48.195,4854,69.6707
43.80062402,48.195,4787,69.1881
43.83322334,48.195,4705,68.593
43.86582266,48.195,4704,68.5857
43.89842198,48.195,4772,69.0797
43.9310213,48.195,4813,69.3758
43.96362062,48.195,4747,68.8985
43.99621994,48.195,4782,69.152
44.02881926,48.195,4738,68.8331
44.06141858,48.195,4743,68.8694
44.0940179,48.195,4798,69.2676
44.12661722,48.195,4615,67.9338
44.15921654,48.195,4752,68.9348
44.19181586,48.195,4720,68.7023
44.22441518,48.195,4646,68.1616
44.2570145,48.195,4912,70.0857
44.28961382,48.195,4859,69.7065
44.32221314,48.195,4861,69.7209
44.35481246,48.195,4703,68.5784
44.38741178,48.195,4698,68.542
44.4200111,48.195,4822,69.4406
44.45261042,48.195,4718,68.6877
44.48520974,48.195,4952,70.3704
44.51780906,48.195,4886,69.8999
44.55040838,48.195,4972,70.5124
44.5830077,48.195,4885,69.8928
44.61560702,48.195,4919,70.1356
44.64820634,48.195,4904,70.0286
44.68080566,48.195,4781,69.1448
44.71340498,48.195,4812,69.3686
44.7460043,48.195,4653,68.2129
44.77860362,48.195,4679,68.4032
44.81120294,48.195,4702,68.5711
44.84380226,48.195,4516,67.2012
44.87640158,48.195,4709,68.6222
44.9090009,48.195,4696,68.5274
44.94160022,48.195,4718,68.6877
44.97419954,48.195,4524,67.2607
45.00679886,48.195,4673,68.3593
45.03939818,48.195,4715,68.6659
45.0719975,48.195,4651,68.1982
45.10459682,48.195,4649,68.1836
45.13719614,48.195,4555,67.4907
45.16979546,48.195,4573,67.624
45.20239478,48.195,4606,67.8675
45.2349941,48.195,4639,68.1102
45.26759342,48.195,4664,68.2935
45.30019274,48.195,4551,67.4611
45.33279206,48.195,4537,67.3573
45.36539138,48.195,4583,67.6979
45.3979907,48.195,4593,67.7717
45.43059002,48.195,4564,67.5574
45.46318934,48.195,4454,66.7383
45.49578866,48.195,4576,67.6461
45.52838798,48.195,4516,67.2012
45.5609873,48.195,4519,67.2235
45.59358662,48.195,4420,66.4831
45.62618594,48.195,4531,67.3127
45.65878526,48.195,4614,67.9264
45.69138458,48.195,4421,66.4906
45.7239839,48.195,4455,66.7458
45.75658322,48.195,4440,66.6333
45.78918254,48.195,4351,65.9621
45.82178186,48.195,4420,66.4831
45.85438118,48.195,4399,66.325
45.8869805,48.195,4407,66.3852
45.91957982,48.195,4392,66.2722
45.95217914,48.195,4479,66.9253
45.98477846,48.195,4359,66.0227
46.01737778,48.195,4419,66.4756
46.0499771,48.195,4465,66.8207
46.08257642,48.195,4419,66.4756
46.11517574,48.195,4264,65.2993
46.14777506,48.195,4303,65.5973
46.18037438,48.195,4352,65.9697
46.2129737,48.195,4452,66.7233
46.24557302,48.195,4378,66.1665
46.27817234,48.195,4285,65.4599
46.31077166,48.195,4424,66.5132
46.34337098,48.195,4299,65.5668
46.3759703,48.195,4290,65.4981
46.40856962,48.195,4459,66.7757
46.44116894,48.195,4285,65.4599
46.47376826,48.195,4282,65.437
46.50636758,48.195,4392,66.2722
46.5389669,48.195,4248,65.1767
46.57156622,48.195,4136,64.3117
46.60416554,48.195,4340,65.8787
46.63676486,48.195,4208,64.8691
46.66936418,48.195,4113,64.1327
46.7019635,48.195,4305,65.6125
46.73456282,48.195,4112,64.1249
46.76716214,48.195,4277,65.3988
46.79976146,48.195,4199,64.7997
46.83236078,48.195,4194,64.7611
46.8649601,48.195,4269,65.3376
46.89755942,48.195,4161,64.5058
46.93015874,48.195,4216,64.9307
46.96275806,48.195,4276,65.3911
46.99535738,48.195,4135,64.304
47.0279567,48.195,4137,64.3195
47.06055602,48.195,4119,64.1794
47.09315534,48.195,4105,64.0703
47.12575466,48.195,4127,64.2417
47.15835398,48.195,4230,65.0385
47.1909533,48.195,4228,65.0231
47.22355262,48.195,4143,64.3661
47.25615194,48.195,4178,64.6375
47.28875126,48.195,4094,63.9844
47.32135058,48.195,4023,63.4271
47.3539499,48.195,4076,63.8436
47.38654922,48.195,4214,64.9153
47.41914854,48.195,4022,63.4192
47.45174786,48.195,4156,64.467
47.48434718,48.195,4122,64.2028
47.5169465,48.195,4271,65.3529
47.54954582,48.195,4038,63.5453
47.58214514,48.195,4188,64.7148
47.61474446,48.195,4079,63.867
47.64734378,48.195,4004,63.2772
47.6799431,48.195,4061,63.726
47.71254242,48.195,4101,64.0391
47.74514174,48.195,3911,62.538
47.77774106,48.195,3999,63.2376
47.81034038,48.195,4007,63.3009
47.8429397,48.195,4010,63.3246
47.87553902,48.195,3997,63.2218
47.90813834,48.195,4059,63.7103
47.94073766,48.195,4013,63.3482
47.97333698,48.195,4031,63.4902
48.0059363,48.195,3955,62.8888
48.03853562,48.195,3972,63.0238
48.07113494,48.195,4032,63.498
48.10373426,48.195,4069,63.7887
48.13633358,48.195,4021,63.4114
48.1689329,48.195,3971,63.0159
48.20153222,48.195,3877,62.2656
48.23413154,48.195,4000,63.2456
48.26673086,48.195,3973,63.0317
48.29933018,48.195,4005,63.2851
48.3319295,48.195,4004,63.2772
48.36452882,48.195,3894,62.4019
48.39712814,48.195,3947,62.8252
48.42972746,48.195,3935,62.7296
48.46232678,48.195,3923,62.6339
48.4949261,48.195,3962,62.9444
48.52752542,48.195,4049,63.6318
48.56012474,48.195,3834,61.9193
48.59272406,48.195,3923,62.6339
48.62532338,48.195,3913,62.554
48.6579227,48.195,3780,61.4817
48.69052202,48.195,3943,62.7933
48.72312134,48.195,3880,62.2896
48.75572066,48.195,3971,63.0159
48.78831998,48.195,3921,62.6179
48.8209193,48.195,3885,62.3298
48.85351862,48.195,3851,62.0564
48.88611794,48.195,3764,61.3514
48.91871726,48.195,3997,63.2218
48.95131658,48.195,3804,61.6766
48.9839159,48.195,3799,61.636
49.01651522,48.195,3785,61.5224
49.04911454,48.195,3779,61.4736
49.08171386,48.195,3746,61.2046
49.11431318,48.195,3833,61.9112
49.1469125,48.195,3717,60.9672
49.17951182,48.195,3741,61.1637
49.21211114,48.195,3728,61.0574
49.24471046,48.195,3726,61.041
49.27730978,48.195,3689,60.7371
49.3099091,48.195,3727,61.0492
49.34250842,48.195,3773,61.4248
49.37510774,48.195,3790,61.563
49.40770706,48.195,3754,61.2699
49.44030638,48.195,3749,61.2291
49.4729057,48.195,3751,61.2454
49.50550502,48.195,3775,61.441
49.53810434,48.195,3746,61.2046
49.57070366,48.195,3754,61.2699
49.60330298,48.195,3621,60.1747
49.6359023,48.195,3588,59.8999
49.66850162,48.195,3715,60.9508
49.70110094,48.195,3590,59.9166
49.73370026,48.195,3595,59.9583
49.76629958,48.195,3638,60.3158
49.7988989,48.195,3593,59.9416
49.83149822,48.195,3706,60.8769
49.86409754,48.195,3566,59.716
49.89669686,48.195,3593,59.9416
49.92929618,48.195,3595,59.9583
49.9618955,48.195,3594,59.95
49.99449482,48.195,3543,59.5231